<?xml version="1.0" ?>
<!-- =================================================================================== -->
<!-- |    This document was autogenerated by xacro from description.xacro              | -->
<!-- |    EDITING THIS FILE BY HAND IS NOT RECOMMENDED                                 | -->
<!-- =================================================================================== -->
<robot name="segway_robot" xmlns:xacro="http://ros.org/wiki/xacro">
  <gazebo>
    <plugin filename="libgazebo_ros_control.so" name="gazebo_ros_control">
      <robotNamespace>/</robotNamespace>
    </plugin>
  </gazebo>
  <!-- Base link is the center of the robot's chassis between the motors projected on the ground -->
  <link name="base_link"/>
  <joint name="base_chassis_joint" type="fixed">
    <origin rpy="0 0 0" xyz="0 0 0.15801795"/>
    <parent link="base_link"/>
    <child link="base_chassis_link"/>
  </joint>
  <link name="base_chassis_link">
    <visual>
      <geometry>
        <mesh filename="package://segway_description/meshes/visual/std_gearbox_chassis.dae"/>
      </geometry>
    </visual>
  </link>
  <link name="inertial_collision_link">
    <inertial>
      <mass value="36.914402"/>
      <origin xyz="-0.043407 0.000037 0.060079"/>
      <inertia ixx="1.182744" ixy="0.017957" ixz="-0.077476" iyx="0.017957" iyy="0.538664" iyz="0.000018" izx="-0.077476" izy="0.000018" izz="1.240229"/>
    </inertial>
    <collision>
      <geometry>
        <mesh filename="package://segway_description/meshes/collision/RMP210_chassis_collision.stl"/>
      </geometry>
    </collision>
  </link>
  <joint name="inertial_collision_joint" type="fixed">
    <parent link="base_chassis_link"/>
    <child link="inertial_collision_link"/>
  </joint>
  <joint name="left_spacer_joint" type="fixed">
    <origin rpy="0 0 0" xyz="0 0.19582 0.00665015"/>
    <parent link="base_chassis_link"/>
    <child link="left_spacer_link"/>
  </joint>
  <link name="left_spacer_link">
    <visual>
      <geometry>
        <mesh filename="package://segway_description/meshes/visual/single_spacer.dae"/>
      </geometry>
    </visual>
  </link>
  <joint name="right_spacer_joint" type="fixed">
    <origin rpy="0 0 3.14159" xyz="0 -0.19582 0.00665015"/>
    <parent link="base_chassis_link"/>
    <child link="right_spacer_link"/>
  </joint>
  <link name="right_spacer_link">
    <visual>
      <geometry>
        <mesh filename="package://segway_description/meshes/visual/single_spacer.dae"/>
      </geometry>
    </visual>
  </link>
  <joint name="mcu_1_battery_joint" type="fixed">
    <origin rpy="0 0 0" xyz="-0.09298 0 0"/>
    <parent link="base_chassis_link"/>
    <child link="mcu_1_battery_link"/>
  </joint>
  <link name="mcu_1_battery_link">
    <visual>
      <geometry>
        <mesh filename="package://segway_description/meshes/visual/battery.dae"/>
      </geometry>
    </visual>
  </link>
  <joint name="ui_box_mount_joint" type="fixed">
    <origin rpy="0 0 0" xyz="-0.1016 0 0.1273"/>
    <parent link="base_chassis_link"/>
    <child link="ui_box_mount_link"/>
  </joint>
  <link name="ui_box_mount_link">
    <visual>
      <geometry>
        <mesh filename="package://segway_description/meshes/visual/ui_box_spacer_mount.dae"/>
      </geometry>
    </visual>
  </link>
  <joint name="ui_box_joint" type="fixed">
    <origin rpy="0 0 0" xyz="-0.1016 0 0.1273"/>
    <parent link="base_chassis_link"/>
    <child link="ui_box_link"/>
  </joint>
  <link name="ui_box_link">
    <visual>
      <geometry>
        <mesh filename="package://segway_description/meshes/visual/ui_box.dae"/>
      </geometry>
    </visual>
  </link>
  <joint name="aux_battery_joint" type="fixed">
    <origin rpy="3.14159 0 0" xyz="-0.07845 0 0.1932753"/>
    <parent link="base_chassis_link"/>
    <child link="aux_battery_link"/>
  </joint>
  <link name="aux_battery_link">
    <visual>
      <geometry>
        <mesh filename="package://segway_description/meshes/visual/battery.dae"/>
      </geometry>
    </visual>
  </link>
  <link name="left_wheel_link">
    <inertial>
      <mass value="4.195729"/>
      <origin xyz="0 0 0"/>
      <inertia ixx="0.063680" ixy="0.000000" ixz="0.000000" iyx="0.000000" iyy="0.121410" iyz="0.000000" izx="0.000000" izy="0.000000" izz="0.063680"/>
    </inertial>
    <visual>
      <origin rpy="0 0 0.0" xyz="0 0 0"/>
      <geometry>
        <mesh filename="package://segway_description/meshes/visual/i2_wheel.dae"/>
      </geometry>
    </visual>
    <collision>
      <origin rpy="1.570795 0 0" xyz="0 0 0"/>
      <geometry>
        <cylinder length="0.092249" radius="0.2405681"/>
      </geometry>
    </collision>
  </link>
  <gazebo reference="left_wheel_link">
    <mu1 value="10.0"/>
    <mu2 value="10.0"/>
    <kp value="10000000.0"/>
    <kd value="10.0"/>
    <fdir1 value="1 0 0"/>
    <minDepth>0.003</minDepth>
  </gazebo>
  <joint name="left_wheel" type="continuous">
    <parent link="base_chassis_link"/>
    <child link="left_wheel_link"/>
    <origin rpy="0 0 0" xyz="0 0.2711955 0.08255015"/>
    <axis rpy="0 0 0" xyz="0 1 0"/>
  </joint>
  <transmission name="left_wheel_trans" type="SimpleTransmission">
    <type>transmission_interface/SimpleTransmission</type>
    <actuator name="left_wheel_motor">
      <mechanicalReduction>1</mechanicalReduction>
    </actuator>
    <joint name="left_wheel">
      <hardwareInterface>VelocityJointInterface</hardwareInterface>
    </joint>
  </transmission>
  <link name="right_wheel_link">
    <inertial>
      <mass value="4.195729"/>
      <origin xyz="0 0 0"/>
      <inertia ixx="0.063680" ixy="0.000000" ixz="0.000000" iyx="0.000000" iyy="0.121410" iyz="0.000000" izx="0.000000" izy="0.000000" izz="0.063680"/>
    </inertial>
    <visual>
      <origin rpy="0 0 3.14159" xyz="0 0 0"/>
      <geometry>
        <mesh filename="package://segway_description/meshes/visual/i2_wheel.dae"/>
      </geometry>
    </visual>
    <collision>
      <origin rpy="1.570795 0 0" xyz="0 0 0"/>
      <geometry>
        <cylinder length="0.092249" radius="0.2405681"/>
      </geometry>
    </collision>
  </link>
  <gazebo reference="right_wheel_link">
    <mu1 value="10.0"/>
    <mu2 value="10.0"/>
    <kp value="10000000.0"/>
    <kd value="10.0"/>
    <fdir1 value="1 0 0"/>
    <minDepth>0.003</minDepth>
  </gazebo>
  <joint name="right_wheel" type="continuous">
    <parent link="base_chassis_link"/>
    <child link="right_wheel_link"/>
    <origin rpy="0 0 0" xyz="0 -0.2711955 0.08255015"/>
    <axis rpy="0 0 0" xyz="0 1 0"/>
  </joint>
  <transmission name="right_wheel_trans" type="SimpleTransmission">
    <type>transmission_interface/SimpleTransmission</type>
    <actuator name="right_wheel_motor">
      <mechanicalReduction>1</mechanicalReduction>
    </actuator>
    <joint name="right_wheel">
      <hardwareInterface>VelocityJointInterface</hardwareInterface>
    </joint>
  </transmission>
</robot>
