<!-- ======================================================
	This file is part of MuJoCo.     
	Copyright 2009-2016 Roboti LLC.
	
	Model 		:: Modular Prosthetic Limb 
		Source		: http://www.jhuapl.edu/prosthetics/scientists/mpl.asp
		Downloaded	: 11Nov'14
		
	Mujoco		:: Advanced physics simulation engine
		Source		: www.roboti.us
		Version		: 1.31
		Released 	: 23Apr16
		
	Author		:: Vikash Kumar, Emo Todorov
		Contacts 	: kumar@roboti.us, todorov@roboti.us
		Last edits 	: 30Apr'16, 15Dec'15
====================================================== -->
<mujoco model="MPL key(v1.31)">
	<include file="include_MPL.xml"/>
	<include file="include_assets.xml"/>

	<contact>
		<exclude body1="world" body2="Key"/>
	</contact>

	<worldbody>	
		<geom name="Wall" type="box" material="MatWood" pos="0 0.1 .15" size="0.07 0.01 0.1501"/>

		<body name="Key" pos="0 0.05 0.2">
			<geom name="teeth" type="box" material="MatFoil" pos="0 0.02 0" size="0.001 0.02 0.01" condim="3" friction="1 .001 .001"/>
			<geom name="Pad" type="cylinder" material="MatFoil" pos="0 -0.035 0" size="0.04 0.003" euler="0 1.57 0" condim="3" friction="1 .001 .001"/>
			<joint name="key" type="hinge" axis="0 1 0" pos="0 0 0" limited="true" range="0 1.57" stiffness="0.02" damping="0.001"/>
		</body>
	</worldbody>
</mujoco>