<?xml version="1.0" encoding="UTF-8"?>
<robot name="carter">
   <link name="chassis">
      <visual>
         <origin rpy="0 0 0" xyz="0 0 0" />
         <geometry>
            <mesh filename="package://carter/meshes/chassis.obj" />
         </geometry>
      </visual>
      <collision>
         <origin rpy="0 0 0" xyz="-0.07764248 -0.000000 0.14683718" />
         <geometry>
            <box size=".55 .40 .54"/>
         </geometry>
      </collision>
      <inertial>
         <origin rpy="0 0 0" xyz="0.000000 0.000000 0.000000" />
         <mass value="30.0" />
         <inertia ixx="0.053345" ixy="0" ixz="0" iyy="0.054469" iyz="0" izz="0.057934" />
      </inertial>
   </link>
   <link name="left_wheel">
      <visual>
         <origin rpy="1.57057 -1.57057 0" xyz="0 0 0" />
         <geometry>
            <mesh filename="package://carter/meshes/side_wheel.obj" />
         </geometry>
      </visual>
      <collision>
         <origin rpy="1.57057 -1.57057 0" xyz="0 -0.05 0" />
         <geometry>
            <cylinder radius = "0.240" length = "0.1"/>
         </geometry>
      </collision>
      <inertial>
         <origin rpy="0 0 0" xyz="0.000000 0.000000 0.000000" />
         <mass value="10.0" />
         <inertia ixx="0.0154743333" ixy="0" ixz="0" iyy="0.0154743333" iyz="0" izz="0.029282" />
      </inertial>
   </link>
   <link name="right_wheel">
      <visual>
         <origin rpy="-1.57057 -1.57057 0" xyz="0 0 0" />
         <geometry>
            <mesh filename="package://carter/meshes/side_wheel.obj" />
         </geometry>
      </visual>
      <collision>
         <origin rpy="-1.57057 -1.57057 0" xyz="0 .05 0" />
         <geometry>
            <cylinder radius = "0.240" length = "0.1"/>
         </geometry>
      </collision>
      <inertial>
         <origin rpy="0 0 0" xyz="0.000000 0.000000 0.000000" />
         <mass value="10.0" />
         <inertia ixx="0.0154743333" ixy="0" ixz="0" iyy="0.0154743333" iyz="0" izz="0.029282" />
      </inertial>
   </link>
   <link name="front_pivot">
      <visual>
         <origin rpy="-1.57057 0 0" xyz="-.03809695 0 -.08961022" />
         <geometry>
            <mesh filename="package://carter/meshes/pivot.obj" />
         </geometry>
      </visual>
      <collision>
         <origin rpy="0 0 0" xyz="-.01 0 -.03" />
         <geometry>
            <box size=".09 .08 .12"/>
         </geometry>
      </collision>
      <inertial>
         <origin rpy="0 0 0" xyz="0.000000 0.000000 0.000000" />
         <mass value="2.0" />
         <inertia ixx="0.0017333333" ixy="0" ixz="0" iyy="0.001875" iyz="0" izz="0.0012083333" />
      </inertial>
   </link>
   <link name="front_wheel">
      <visual>
         <origin rpy="1.57057 0 0" xyz="0 0 0" />
         <geometry>
            <mesh filename="package://carter/meshes/front_wheel.obj" />
         </geometry>
      </visual>
      <collision>
         <origin rpy="1.57057 0 0" xyz="0 0 0" />
         <geometry>
            <cylinder radius=".076" length=".048" />
         </geometry>
      </collision>
      <inertial>
         <origin rpy="0 0 0" xyz="0.000000 0.000000 0.000000" />
         <mass value="2.0" />
         <inertia ixx="0.001636" ixy="0" ixz="0" iyy="0.001636" iyz="0" izz="0.002888" />
      </inertial>
   </link>
   <joint name="left_axle" type="revolute">
      <origin rpy="0 0 0" xyz="0 0.31420517 0" />
      <axis xyz="0 1 0" />
      <parent link="chassis" />
      <child link="left_wheel" />
   </joint>
   <joint name="right_axle" type="revolute">
      <origin rpy="0 0 0" xyz="0 -0.31420517 0" />
      <axis xyz="0 1 0" />
      <parent link="chassis" />
      <child link="right_wheel" />
   </joint>
   <joint name="front_axle" type="revolute">
      <origin rpy="0 0 0" xyz="-.03809695 0 -.08961022" />
      <axis xyz="0 1 0" />
      <parent link="front_pivot" />
      <child link="front_wheel" />
   </joint>
   <joint name="front_pivot" type="revolute">
      <origin rpy="0 0 0" xyz="-0.31613607 0 -.0758" />
      <axis xyz="0 0 1" />
      <parent link="chassis" />
      <child link="front_pivot" />
   </joint>
   <!-- <link name="zed_link">
      <inertial>
         <origin rpy="0 0 0" xyz="0.000000 0.000000 0.000000" />
         <mass value="1.0" />
         <inertia ixx="1" ixy="0" ixz="0" iyy="1" iyz="0" izz="1" />
      </inertial>
   </link>
   <link name="lidar_link">
      <inertial>
         <origin rpy="0 0 0" xyz="0.000000 0.000000 0.000000" />
         <mass value="1.0" />
         <inertia ixx="1" ixy="0" ixz="0" iyy="1" iyz="0" izz="1" />
      </inertial>
   </link>
  <joint name="lidar_joint" type="fixed">
    <origin rpy="0 0 0" xyz="-.06 0 0.38"/>
    <parent link="chassis"/>
    <child link="lidar_link"/>
  </joint>
   <joint name="zed_pivot" type="revolute">
      <origin rpy="0 0 0" xyz="0.11 0 0.31"/>
      <axis xyz="0 0 1" />
      <parent link="chassis" />
      <child link="zed_link" />
   </joint> -->
</robot>