<!-- These are atlas torso and limb models, for full Atlas robot model, please see
     xacro files containing fully assembed robots in atlas_description/robots/ -->
<robot name="drc_skeleton">
    <link name="l_clav">
        <inertial>
            <mass value="3.45" />
            <origin xyz="0 0.048 0.084" rpy="0 -0 0" />
            <inertia ixx="0.011" ixy="0" ixz="0" iyy="0.009" iyz="-0.004" izz="0.004" />
        </inertial>
        <visual>
            <origin xyz="0 0 0" rpy="0 -0 0" />
            <geometry>
                <mesh filename="package://atlas_description/meshes_v3/l_clav.dae" scale="1 1 1" />
            </geometry>
        </visual>
        <collision>
          <origin rpy="0 1.5707963267949 0" xyz="0 0.144 0.202"/>
          <geometry>
            <cylinder radius="0.045" length="0.1525"/>
          </geometry>
        </collision>
        <collision>
          <origin rpy="1.0472 0 0" xyz="-0.005 0.075 0.13"/>
          <geometry>
            <box size="0.13 0.15 0.05"/>
          </geometry>
        </collision>
        <collision>
          <origin rpy="1.0472 0 0" xyz="0.003 0.045 0.162"/>
          <geometry>
            <box size="0.045 0.03 0.04"/>
          </geometry>
        </collision>
    </link>
    <link name="l_farm">
        <inertial>
            <mass value="3.388" />
            <origin xyz="0 -0.065 0" rpy="0 -0 0" />
            <inertia ixx="0.00656" ixy="0" ixz="0" iyy="0.00358" iyz="0" izz="0.00656" />
        </inertial>
        <visual>
            <origin xyz="0 0 0" rpy="0 -0 0" />
            <geometry>
                <mesh filename="package://atlas_description/meshes_v3/l_farm.dae" scale="1 1 1" />
            </geometry>
        </visual>
        <collision>
          <origin rpy="0 1.5708 0" xyz="0.0 0.13 0.004"/>
          <geometry>
            <cylinder radius="0.045" length="0.125"/>
          </geometry>
        </collision>
        <collision>
          <origin rpy="0 0 0" xyz="0.001 0.053 -0.002"/>
          <geometry>
            <box size="0.135 0.1 0.045"/>
          </geometry>
        </collision>
    </link>
    <link name="l_foot">
        <inertial>
            <mass value="2.05" />
            <origin xyz="0.027 0 -0.067" rpy="0 -0 0" />
            <inertia ixx="0.002" ixy="0" ixz="0" iyy="0.007" iyz="0" izz="0.008" />
        </inertial>
        <visual>
            <origin xyz="0 0 0" rpy="0 -0 0" />
            <geometry>
                <mesh filename="package://atlas_description/meshes_v3/l_foot.dae" scale="1 1 1" />
            </geometry>
        </visual>
        <!--
        <collision>
            <origin xyz="0 0 0" rpy="0 -0 0" />
            <geometry>
                <mesh filename="package://atlas_description/meshes_v3/l_foot.stl" scale="1 1 1" />
            </geometry>
        </collision>
        -->
        <collision>
          <origin xyz="0.048 0 -0.056119" rpy="0 0 0"/>
          <geometry>
            <box size="0.26 0.124887 0.05"/>
          </geometry>
        </collision>
        <!-- ankle FIXME: adding this collision body destabilizes robot, shouldn't
        <collision>
          <origin xyz="0.0 0 -0.0528735" rpy="0 0 0"/>
          <geometry>
            <cylinder radius="0.0373" length="0.037827"/>
          </geometry>
        </collision>
        -->
    </link>
    <link name="l_hand">
        <inertial>
            <mass value="2.509" />
            <origin xyz="0 0 0" rpy="0 -0 0" />
            <inertia ixx="0.00265" ixy="0" ixz="0" iyy="0.00446" iyz="0" izz="0.00446" />
        </inertial>
        <visual>
            <origin xyz="0 0 0" rpy="0 -0 0" />
            <geometry>
                <mesh filename="package://atlas_description/meshes_v3/l_hand.dae" scale="1 1 1" />
            </geometry>
        </visual>
        <collision>
          <origin rpy="1.5707963267949 0 0" xyz="0.001 0.1 0.01"/>
          <geometry>
            <cylinder radius="0.03" length="0.05"/>
          </geometry>
        </collision>
        <collision>
          <origin rpy="0 0 0" xyz="0.001 0.05 0.01"/>
          <geometry>
            <box size="0.13 0.09 0.07"/>
          </geometry>
        </collision>
    </link>
    <link name="l_larm">
        <inertial>
            <mass value="2.509" />
            <origin xyz="0 0 0" rpy="0 -0 0" />
            <inertia ixx="0.00265" ixy="0" ixz="0" iyy="0.00446" iyz="0" izz="0.00446" />
        </inertial>
        <visual>
            <origin xyz="0 0 0" rpy="0 -0 0" />
            <geometry>
                <mesh filename="package://atlas_description/meshes_v3/l_larm.dae" scale="1 1 1" />
            </geometry>
        </visual>
        <collision>
          <origin rpy="1.5707963267949 0 0" xyz="0.001 0.127 0.00"/>
          <geometry>
            <cylinder radius="0.045" length="0.125"/>
          </geometry>
        </collision>
        <collision>
          <origin rpy="0 0 0" xyz="0.001 0.051 0.0"/>
          <geometry>
            <box size="0.135 0.15 0.06"/>
          </geometry>
        </collision>
    </link>
    <link name="l_lglut">
        <inertial>
            <mass value="0.866" />
            <origin xyz="0.0133341 0.0170484 -0.0312052" rpy="0 -0 0" />
            <inertia ixx="0.000691326" ixy="-2.24344e-05" ixz="2.50508e-06" iyy="0.00126856" iyz="0.000137862" izz="0.00106487" />
        </inertial>
        <visual>
            <origin xyz="0 0 0" rpy="0 -0 0" />
            <geometry>
                <mesh filename="package://atlas_description/meshes_v3/l_lglut.dae" scale="1 1 1" />
            </geometry>
        </visual>
        <!--
        <collision>
            <origin xyz="0 0 0" rpy="0 -0 0" />
            <geometry>
                <mesh filename="package://atlas_description/meshes_v3/l_lglut.stl" scale="1 1 1" />
            </geometry>
        </collision>
        -->
        <collision>
          <origin rpy="1.5707963267949 0 0" xyz="0.05 0.022488 -0.05"/>
          <geometry>
            <cylinder radius="0.02009687" length="0.060306"/>
          </geometry>
        </collision>
        <collision>
          <origin rpy="0 1.5707963267949 0" xyz="0.0115 0 0"/>
          <geometry>
            <cylinder radius="0.02" length="0.144"/>
          </geometry>
        </collision>
    </link>
    <link name="l_lleg">
        <inertial>
            <mass value="5.479" />
            <origin xyz="0.001 0 -0.187" rpy="0 -0 0" />
            <inertia ixx="0.077" ixy="0" ixz="-0.003" iyy="0.076" iyz="0" izz="0.01" />
        </inertial>
        <visual>
            <origin xyz="0 0 0" rpy="0 -0 0" />
            <geometry>
                <mesh filename="package://atlas_description/meshes_v3/l_lleg.dae" scale="1 1 1" />
            </geometry>
        </visual>
        <!--
        <collision>
            <origin xyz="0 0 0" rpy="0 -0 0" />
            <geometry>
                <mesh filename="package://atlas_description/meshes_v3/l_lleg.stl" scale="1 1 1" />
            </geometry>
        </collision>
        -->
        <collision>
          <origin rpy="0 0.10 0" xyz="0.02 0.00295 -0.18"/>
          <geometry>
            <cylinder radius="0.07" length="0.40"/>
          </geometry>
        </collision>
    </link>
    <link name="l_scap">
        <inertial>
            <mass value="3.012" />
            <origin xyz="0 0 0" rpy="0 -0 0" />
            <inertia ixx="0.00319" ixy="0" ixz="0" iyy="0.00583" iyz="0" izz="0.00583" />
        </inertial>
        <visual>
            <origin xyz="0 0 0" rpy="0 -0 0" />
            <geometry>
                <mesh filename="package://atlas_description/meshes_v3/l_scap.dae" scale="1 1 1" />
            </geometry>
        </visual>
        <collision>
          <origin rpy="1.5707963267949 0 0" xyz="0.001 0.12651 0.01521"/>
          <geometry>
            <cylinder radius="0.045" length="0.125"/>
          </geometry>
        </collision>
        <collision>
          <origin rpy="0 0 0" xyz="0.001 0.05 0.016"/>
          <geometry>
            <box size="0.15 0.15 0.06"/>
          </geometry>
        </collision>
    </link>
    <link name="l_talus">
        <inertial>
            <mass value="0.125" />
            <origin xyz="0 0 0" rpy="0 -0 0" />
            <inertia ixx="1.01674e-05" ixy="0" ixz="0" iyy="8.42775e-06" iyz="0" izz="1.30101e-05" />
        </inertial>
        <visual>
            <origin xyz="0 0 0" rpy="0 -0 0" />
            <geometry>
                <mesh filename="package://atlas_description/meshes_v3/l_talus.dae" scale="1 1 1" />
            </geometry>
        </visual>
        <!--
        <collision>
            <origin xyz="0 0 0" rpy="0 -0 0" />
            <geometry>
                <mesh filename="package://atlas_description/meshes_v3/l_talus.stl" scale="1 1 1" />
            </geometry>
        </collision>
        -->
        <collision>
          <origin rpy="0 1.5707963267949 0" xyz="0 0 0"/>
          <geometry>
            <cylinder radius="0.010181" length="0.029542"/>
          </geometry>
        </collision>
        <collision>
          <origin rpy="1.5707963267949 0 0" xyz="0 0 0"/>
          <geometry>
            <cylinder radius="0.010348" length="0.010059"/>
          </geometry>
        </collision>
    </link>
    <link name="l_uarm">
        <inertial>
            <mass value="3.388" />
            <origin xyz="0 -0.065 0" rpy="0 -0 0" />
            <inertia ixx="0.00656" ixy="0" ixz="0" iyy="0.00358" iyz="0" izz="0.00656" />
        </inertial>
        <visual>
            <origin xyz="0 0 0" rpy="0 -0 0" />
            <geometry>
                <mesh filename="package://atlas_description/meshes_v3/l_uarm.dae" scale="1 1 1" />
            </geometry>
        </visual>
        <collision>
          <origin rpy="0 1.5708 0" xyz="0.001 0.111 0.0"/>
          <geometry>
            <cylinder radius="0.045" length="0.125"/>
          </geometry>
        </collision>
        <collision>
          <origin rpy="0 1.5707963267949 0" xyz="0.001 0.043 0.01"/>
          <geometry>
            <box size="0.04 0.07 0.13"/>
          </geometry>
        </collision>
    </link>
    <link name="l_uglut">
        <inertial>
            <mass value="0.648" />
            <origin xyz="0.00529262 -0.00344732 0.00313046" rpy="0 -0 0" />
            <inertia ixx="0.00074276" ixy="-3.79607e-08" ixz="-2.79549e-05" iyy="0.000688179" iyz="-3.2735e-08" izz="0.00041242" />
        </inertial>
        <visual>
            <origin xyz="0 0 0" rpy="0 -0 0" />
            <geometry>
                <mesh filename="package://atlas_description/meshes_v3/l_uglut.dae" scale="1 1 1" />
            </geometry>
        </visual>
        <!--
        <collision>
            <origin xyz="0 0 0" rpy="0 -0 0" />
            <geometry>
                <mesh filename="package://atlas_description/meshes_v3/l_uglut.stl" scale="1 1 1" />
            </geometry>
        </collision>
        -->
        <collision>
          <origin rpy="0 1.5707963267949 0" xyz="0 0 0"/>
          <geometry>
            <cylinder radius="0.019096" length="0.078396"/>
          </geometry>
        </collision>
        <collision>
          <origin rpy="0 0 0" xyz="0 0 0"/>
          <geometry>
            <cylinder radius="0.019841" length="0.080842"/>
          </geometry>
        </collision>
    </link>
    <link name="l_uleg">
        <inertial>
            <mass value="9.209" />
            <origin xyz="0 0 -0.21" rpy="0 -0 0" />
            <inertia ixx="0.09" ixy="0" ixz="0" iyy="0.09" iyz="0" izz="0.02" />
        </inertial>
        <visual>
            <origin xyz="0 0 0" rpy="0 -0 0" />
            <geometry>
                <mesh filename="package://atlas_description/meshes_v3/l_uleg.dae" scale="1 1 1" />
            </geometry>
        </visual>
        <!--
        <collision>
            <origin xyz="0 0 0" rpy="0 -0 0" />
            <geometry>
                <mesh filename="package://atlas_description/meshes_v3/l_uleg.stl" scale="1 1 1" />
            </geometry>
        </collision>
        -->
        <collision>
          <origin rpy="0 0 0" xyz="-0.0179 0.02085 -0.13"/>
          <geometry>
            <cylinder radius="0.1" length="0.10"/>
          </geometry>
        </collision>
        <collision>
          <origin rpy="0 -0.3 0" xyz="-0.03 0.01 -0.23"/>
          <geometry>
            <cylinder radius="0.07" length="0.15"/>
          </geometry>
        </collision>
        <collision>
          <origin rpy="0 0.3 0" xyz="-0.005 0.01 -0.23"/>
          <geometry>
            <cylinder radius="0.07" length="0.15"/>
          </geometry>
        </collision>
        <collision>
          <origin rpy="-0.25 0 0" xyz="-0.02 0.03 -0.23"/>
          <geometry>
            <cylinder radius="0.07" length="0.15"/>
          </geometry>
        </collision>
        <!-- to cover the logo shield -->
        <collision>
          <origin rpy="-0.15 0.13 0" xyz="0.005 0.03 -0.26"/>
          <geometry>
            <cylinder radius="0.07" length="0.15"/>
          </geometry>
        </collision>
        <!-- inside strut -->
        <collision>
          <origin rpy="-0.052 0.0 0" xyz="-0.005 -0.023 -0.058"/>
          <geometry>
            <box size="0.07 0.016 0.15"/>
          </geometry>
        </collision>
        <!-- outside strut -->
        <collision>
          <origin rpy="0.0 0.0 0" xyz="-0.015 0.078 -0.055"/>
          <geometry>
            <box size="0.07 0.038 0.15"/>
          </geometry>
        </collision>
    </link>
    <link name="ltorso">
        <inertial>
            <mass value="2.409" />
            <origin xyz="-0.0112984 -3.15366e-06 0.0746835" rpy="0 -0 0" />
            <inertia ixx="0.0039092" ixy="-5.04491e-08" ixz="-0.000342157" iyy="0.00341694" iyz="4.87119e-07" izz="0.00174492" />
        </inertial>
        <visual>
            <origin xyz="0 0 0" rpy="0 -0 0" />
            <geometry>
                <mesh filename="package://atlas_description/meshes_v3/ltorso.dae" scale="1 1 1" />
            </geometry>
        </visual>
    </link>
    <link name="mtorso">
        <inertial>
            <mass value="0.69" />
            <origin xyz="-0.00816266 -0.0131245 0.0305974" rpy="0 -0 0" />
            <inertia ixx="0.000454181" ixy="-6.10764e-05" ixz="3.94009e-05" iyy="0.000483282" iyz="5.27463e-05" izz="0.000444215" />
        </inertial>
        <visual>
            <origin xyz="0 0 0" rpy="0 -0 0" />
            <geometry>
                <mesh filename="package://atlas_description/meshes_v3/mtorso.dae" scale="1 1 1" />
            </geometry>
        </visual>
        <collision>
          <origin rpy="1.5707963267949 0 0" xyz="0 0 0"/>
          <geometry>
            <cylinder radius="0.017" length="0.06"/>
          </geometry>
        </collision>
        <collision>
          <origin rpy="0 0 0" xyz="0.0 0 0.05"/>
          <geometry>
            <cylinder radius="0.02" length="0.08"/>
          </geometry>
        </collision>
    </link>
    <link name="pelvis">
        <inertial>
            <mass value="17.882" />
            <origin xyz="0.0111 0 0.0271" rpy="0 -0 0" />
            <inertia ixx="0.1244" ixy="0.0008" ixz="-0.0007" iyy="0.0958" iyz="-0.0005" izz="0.1167" />
        </inertial>
        <visual>
            <origin xyz="0 0 0" rpy="0 -0 0" />
            <geometry>
                <mesh filename="package://atlas_description/meshes_v3/pelvis.dae" scale="1 1 1" />
            </geometry>
        </visual>
        <collision>
          <origin rpy="1.5707963267949 0 0" xyz="0.046 0.0 -0.02"/>
          <geometry>
            <cylinder radius="0.11" length="0.06"/>
          </geometry>
        </collision>
        <collision>
          <origin rpy="1.5707963267949 0 0" xyz="-0.03 0.0 -0.02"/>
          <geometry>
            <cylinder radius="0.11" length="0.06"/>
          </geometry>
        </collision>
        <collision>
          <origin rpy="0 0 0" xyz="0.01 0.042 0.09"/>
          <geometry>
            <cylinder radius="0.16" length="0.05"/>
          </geometry>
        </collision>
        <collision>
          <origin rpy="0 0 0" xyz="0.01 -0.042 0.09"/>
          <geometry>
            <cylinder radius="0.16" length="0.05"/>
          </geometry>
        </collision>
        <collision>
          <origin rpy="0 0 0" xyz="-0.1 0 -0.05"/>
          <geometry>
            <box size="0.1 0.15 0.2"/>
          </geometry>
        </collision>

    </link>
    <link name="r_clav">
        <inertial>
            <mass value="3.45" />
            <origin xyz="0 -0.048 0.084" rpy="0 -0 0" />
            <inertia ixx="0.011" ixy="0" ixz="0" iyy="0.009" iyz="0.004" izz="0.004" />
        </inertial>
        <visual>
            <origin xyz="0 0 0" rpy="0 -0 0" />
            <geometry>
                <mesh filename="package://atlas_description/meshes_v3/r_clav.dae" scale="1 1 1" />
            </geometry>
        </visual>
        <collision>
          <origin rpy="0 1.5707963267949 0" xyz="0 -0.144 0.202"/>
          <geometry>
            <cylinder radius="0.045" length="0.1525"/>
          </geometry>
        </collision>
        <collision>
          <origin rpy="-1.0472 0 0" xyz="-0.005 -0.075 0.13"/>
          <geometry>
            <box size="0.13 0.15 0.05"/>
          </geometry>
        </collision>
        <collision>
          <origin rpy="-1.0472 0 0" xyz="0.003 -0.045 0.162"/>
          <geometry>
            <box size="0.045 0.03 0.04"/>
          </geometry>
        </collision>
    </link>
    <link name="r_farm">
        <inertial>
            <mass value="3.388" />
            <origin xyz="0 0.065 0" rpy="0 -0 0" />
            <inertia ixx="0.00656" ixy="0" ixz="0" iyy="0.00358" iyz="0" izz="0.00656" />
        </inertial>
        <visual>
            <origin xyz="0 0 0" rpy="0 -0 0" />
            <geometry>
                <mesh filename="package://atlas_description/meshes_v3/r_farm.dae" scale="1 1 1" />
            </geometry>
        </visual>
        <collision>
          <origin rpy="0 1.5708 0" xyz="0.0 -0.13 0.004"/>
          <geometry>
            <cylinder radius="0.045" length="0.125"/>
          </geometry>
        </collision>
        <collision>
          <origin rpy="0 0 0" xyz="0.001 -0.053 -0.002"/>
          <geometry>
            <box size="0.135 0.1 0.045"/>
          </geometry>
        </collision>
    </link>
    <link name="r_foot">
        <inertial>
            <mass value="2.05" />
            <origin xyz="0.027 0 -0.067" rpy="0 -0 0" />
            <inertia ixx="0.002" ixy="0" ixz="0" iyy="0.007" iyz="0" izz="0.008" />
        </inertial>
        <visual>
            <origin xyz="0 0 0" rpy="0 -0 0" />
            <geometry>
                <mesh filename="package://atlas_description/meshes_v3/r_foot.dae" scale="1 1 1" />
            </geometry>
        </visual>
        <!--
        <collision>
            <origin xyz="0 0 0" rpy="0 -0 0" />
            <geometry>
                <mesh filename="package://atlas_description/meshes_v3/r_foot.stl" scale="1 1 1" />
            </geometry>
        </collision>
        -->
        <collision>
          <origin xyz="0.048 0 -0.056119" rpy="0 0 0"/>
          <geometry>
            <box size="0.26 0.124887 0.05"/>
          </geometry>
        </collision>
        <!-- ankle FIXME: adding this collision body destabilizes robot, shouldn't
        <collision>
          <origin xyz="0.0 0 -0.0528735" rpy="0 0 0"/>
          <geometry>
            <cylinder radius="0.0373" length="0.037827"/>
          </geometry>
        </collision>
        -->
    </link>
    <link name="r_hand">
        <inertial>
            <mass value="2.509" />
            <origin xyz="0 0 0" rpy="0 -0 0" />
            <inertia ixx="0.00265" ixy="0" ixz="0" iyy="0.00446" iyz="0" izz="0.00446" />
        </inertial>
        <visual>
            <origin xyz="0 0 0" rpy="0 -0 0" />
            <geometry>
                <mesh filename="package://atlas_description/meshes_v3/r_hand.dae" scale="1 1 1" />
            </geometry>
        </visual>
        <collision>
          <origin rpy="1.5707963267949 0 0" xyz="0.001 -0.1 0.01"/>
          <geometry>
            <cylinder radius="0.03" length="0.05"/>
          </geometry>
        </collision>
        <collision>
          <origin rpy="0 0 0" xyz="0.001 -0.05 0.01"/>
          <geometry>
            <box size="0.13 0.09 0.07"/>
          </geometry>
        </collision>
    </link>
    <link name="r_larm">
        <inertial>
            <mass value="2.509" />
            <origin xyz="0 0 0" rpy="0 -0 0" />
            <inertia ixx="0.00265" ixy="0" ixz="0" iyy="0.00446" iyz="0" izz="0.00446" />
        </inertial>
        <visual>
            <origin xyz="0 0 0" rpy="0 -0 0" />
            <geometry>
                <mesh filename="package://atlas_description/meshes_v3/r_larm.dae" scale="1 1 1" />
            </geometry>
        </visual>
        <collision>
          <origin rpy="1.5707963267949 0 0" xyz="0.001 -0.127 0.00"/>
          <geometry>
            <cylinder radius="0.045" length="0.125"/>
          </geometry>
        </collision>
        <collision>
          <origin rpy="0 0 0" xyz="0.001 -0.051 0.0"/>
          <geometry>
            <box size="0.135 0.15 0.06"/>
          </geometry>
        </collision>
    </link>
    <link name="r_lglut">
        <inertial>
            <mass value="0.866" />
            <origin xyz="0.0133341 -0.0170484 -0.0312052" rpy="0 -0 0" />
            <inertia ixx="0.000691326" ixy="2.24344e-05" ixz="2.50508e-06" iyy="0.00126856" iyz="-0.000137862" izz="0.00106487" />
        </inertial>
        <visual>
            <!-- there appears to be a bug in the visuals provided, not aligned with the other left one in x-direction
            <origin xyz="0 0 0" rpy="0 -0 0" />
            -->
            <origin xyz="0.01 0 0" rpy="0 -0 0" />
            <geometry>
                <mesh filename="package://atlas_description/meshes_v3/r_lglut.dae" scale="1 1 1" />
            </geometry>
        </visual>
        <!--
        <collision>
            <origin xyz="0 0 0" rpy="0 -0 0" />
            <geometry>
                <mesh filename="package://atlas_description/meshes_v3/r_lglut.stl" scale="1 1 1" />
            </geometry>
        </collision>
        -->
        <collision>
          <origin rpy="1.5707963267949 0 0" xyz="0.05 -0.022488 -0.05"/>
          <geometry>
            <cylinder radius="0.02009687" length="0.060306"/>
          </geometry>
        </collision>
        <collision>
          <origin rpy="0 1.5707963267949 0" xyz="0.0105 0 0"/>
          <geometry>
            <cylinder radius="0.02" length="0.142"/>
          </geometry>
        </collision>
    </link>
    <link name="r_lleg">
        <inertial>
            <mass value="5.479" />
            <origin xyz="0.001 0 -0.187" rpy="0 -0 0" />
            <inertia ixx="0.077" ixy="-0" ixz="-0.003" iyy="0.076" iyz="-0" izz="0.01" />
        </inertial>
        <visual>
            <origin xyz="0 0 0" rpy="0 -0 0" />
            <geometry>
                <mesh filename="package://atlas_description/meshes_v3/r_lleg.dae" scale="1 1 1" />
            </geometry>
        </visual>
        <!--
        <collision>
            <origin xyz="0 0 0" rpy="0 -0 0" />
            <geometry>
                <mesh filename="package://atlas_description/meshes_v3/r_lleg.stl" scale="1 1 1" />
            </geometry>
        </collision>
        -->
        <collision>
          <origin rpy="0 0.10 0" xyz="0.02 -0.00295 -0.18"/>
          <geometry>
            <cylinder radius="0.07" length="0.40"/>
          </geometry>
        </collision>
    </link>
    <link name="r_scap">
        <inertial>
            <mass value="3.012" />
            <origin xyz="0 0 0" rpy="0 -0 0" />
            <inertia ixx="0.00319" ixy="0" ixz="0" iyy="0.00583" iyz="0" izz="0.00583" />
        </inertial>
        <visual>
            <origin xyz="0 0 0" rpy="0 -0 0" />
            <geometry>
                <mesh filename="package://atlas_description/meshes_v3/r_scap.dae" scale="1 1 1" />
            </geometry>
        </visual>
        <collision>
          <origin rpy="1.5707963267949 0 0" xyz="0.001 -0.12651 0.01521"/>
          <geometry>
            <cylinder radius="0.045" length="0.125"/>
          </geometry>
        </collision>
        <collision>
          <origin rpy="0 0 0" xyz="0.001 -0.05 0.016"/>
          <geometry>
            <box size="0.15 0.15 0.06"/>
          </geometry>
        </collision>
    </link>
    <link name="r_talus">
        <inertial>
            <mass value="0.125" />
            <origin xyz="0 0 0" rpy="0 -0 0" />
            <inertia ixx="1.01674e-05" ixy="0" ixz="0" iyy="8.42775e-06" iyz="0" izz="1.30101e-05" />
        </inertial>
        <visual>
            <origin xyz="0 0 0" rpy="0 -0 0" />
            <geometry>
                <mesh filename="package://atlas_description/meshes_v3/r_talus.dae" scale="1 1 1" />
            </geometry>
        </visual>
        <!--
        <collision>
            <origin xyz="0 0 0" rpy="0 -0 0" />
            <geometry>
                <mesh filename="package://atlas_description/meshes_v3/r_talus.stl" scale="1 1 1" />
            </geometry>
        </collision>
        -->
        <collision>
          <origin rpy="0 1.5707963267949 0" xyz="0 0 0"/>
          <geometry>
            <cylinder radius="0.010181" length="0.029542"/>
          </geometry>
        </collision>
        <collision>
          <origin rpy="1.5707963267949 0 0" xyz="0 0 0"/>
          <geometry>
            <cylinder radius="0.010348" length="0.010059"/>
          </geometry>
        </collision>
    </link>
    <link name="r_uarm">
        <inertial>
            <mass value="3.388" />
            <origin xyz="0 0.065 0" rpy="0 -0 0" />
            <inertia ixx="0.00656" ixy="0" ixz="0" iyy="0.00358" iyz="0" izz="0.00656" />
        </inertial>
        <visual>
            <origin xyz="0 0 0" rpy="0 -0 0" />
            <geometry>
                <mesh filename="package://atlas_description/meshes_v3/r_uarm.dae" scale="1 1 1" />
            </geometry>
        </visual>
        <collision>
          <origin rpy="0 1.5708 0" xyz="0.001 -0.111 0.0"/>
          <geometry>
            <cylinder radius="0.045" length="0.125"/>
          </geometry>
        </collision>
        <collision>
          <origin rpy="0 1.5707963267949 0" xyz="0.001 -0.043 0.01"/>
          <geometry>
            <box size="0.04 0.07 0.13"/>
          </geometry>
        </collision>
    </link>
    <link name="r_uglut">
        <inertial>
            <mass value="0.648" />
            <origin xyz="0.00529262 0.00344732 0.00313046" rpy="0 -0 0" />
            <inertia ixx="0.00074276" ixy="3.79607e-08" ixz="-2.79549e-05" iyy="0.000688179" iyz="3.2735e-08" izz="0.00041242" />
        </inertial>
        <visual>
            <origin xyz="0 0 0" rpy="0 -0 0" />
            <geometry>
                <mesh filename="package://atlas_description/meshes_v3/r_uglut.dae" scale="1 1 1" />
            </geometry>
        </visual>
        <!--
        <collision>
            <origin xyz="0 0 0" rpy="0 -0 0" />
            <geometry>
                <mesh filename="package://atlas_description/meshes_v3/r_uglut.stl" scale="1 1 1" />
            </geometry>
        </collision>
        -->
        <collision>
          <origin rpy="0 1.5707963267949 0" xyz="0 0 0"/>
          <geometry>
            <cylinder radius="0.019096" length="0.078396"/>
          </geometry>
        </collision>
        <collision>
          <origin rpy="0 0 0" xyz="0 0 0"/>
          <geometry>
            <cylinder radius="0.019841" length="0.080842"/>
          </geometry>
        </collision>
    </link>
    <link name="r_uleg">
        <inertial>
            <mass value="9.209" />
            <origin xyz="0 0 -0.21" rpy="0 -0 0" />
            <inertia ixx="0.09" ixy="0" ixz="0" iyy="0.09" iyz="0" izz="0.02" />
        </inertial>
        <visual>
            <origin xyz="0 0 0" rpy="0 -0 0" />
            <geometry>
                <mesh filename="package://atlas_description/meshes_v3/r_uleg.dae" scale="1 1 1" />
            </geometry>
        </visual>
        <!--
        <collision>
            <origin xyz="0 0 0" rpy="0 -0 0" />
            <geometry>
                <mesh filename="package://atlas_description/meshes_v3/r_uleg.stl" scale="1 1 1" />
            </geometry>
        </collision>
        -->
        <collision>
          <origin rpy="0 0 0" xyz="-0.0179 -0.02085 -0.13"/>
          <geometry>
            <cylinder radius="0.1" length="0.10"/>
          </geometry>
        </collision>
        <collision>
          <origin rpy="0 -0.3 0" xyz="-0.03 -0.01 -0.23"/>
          <geometry>
            <cylinder radius="0.07" length="0.15"/>
          </geometry>
        </collision>
        <collision>
          <origin rpy="0 0.3 0" xyz="-0.005 -0.01 -0.23"/>
          <geometry>
            <cylinder radius="0.07" length="0.15"/>
          </geometry>
        </collision>
        <collision>
          <origin rpy="0.25 0 0" xyz="-0.02 -0.03 -0.23"/>
          <geometry>
            <cylinder radius="0.07" length="0.15"/>
          </geometry>
        </collision>
        <!-- to cover the logo shield -->
        <collision>
          <origin rpy="0.15 0.13 0" xyz="0.005 -0.03 -0.26"/>
          <geometry>
            <cylinder radius="0.07" length="0.15"/>
          </geometry>
        </collision>
        <!-- inside strut -->
        <collision>
          <origin rpy="0.052 0.0 0" xyz="-0.005 0.023 -0.058"/>
          <geometry>
            <box size="0.07 0.016 0.15"/>
          </geometry>
        </collision>
        <!-- outside strut -->
        <collision>
          <origin rpy="0.0 0.0 0" xyz="-0.015 -0.078 -0.055"/>
          <geometry>
            <box size="0.07 0.038 0.15"/>
          </geometry>
        </collision>
    </link>
    <!-- with backpack -->
    <link name="utorso">
        <inertial>
            <mass value="52.007" />
            <origin xyz="-0.0923 0 0.3" rpy="0 -0 0" />
            <inertia ixx="1.466" ixy="0.00362" ixz="0.336" iyy="1.51" iyz="0.001" izz="1.3" />
        </inertial>
        <visual>
            <origin xyz="0 0 0" rpy="0 -0 0" />
            <geometry>
                <mesh filename="package://atlas_description/meshes_v3/utorso.dae" scale="1 1 1" />
            </geometry>
        </visual>
        <collision>
            <origin xyz="-0.048395 0 0.20" rpy="0 0 0" />
            <geometry>
              <box size="0.530175 0.25 0.340"/>
            </geometry>
        </collision>
        <collision>
            <origin xyz="-0.2 0 0.46" rpy="0 0 0" />
            <geometry>
              <box size="0.266306 0.381719 0.18"/>
            </geometry>
        </collision>
        <collision>
            <origin xyz="-0.2 0 0.58" rpy="0 0 0" />
            <geometry>
              <box size="0.266306 0.223 0.091"/>
            </geometry>
        </collision>
        <collision>
            <origin xyz="0.05 0 0.45" rpy="0 0 0" />
            <geometry>
              <box size="0.4 0.3 0.18"/>
            </geometry>
        </collision>
        <collision>
            <origin xyz="0.15 0 0.724" rpy="1.5707 0 0" />
            <geometry>
              <cylinder radius="0.008" length="0.1"/>
            </geometry>
        </collision>
        <collision>
            <origin xyz="-0.002 0 0.71" rpy="1.5707 0 0" />
            <geometry>
              <cylinder radius="0.008" length="0.13"/>
            </geometry>
        </collision>

        <collision>
            <origin xyz="0.02 0.163 0.57" rpy="0 1.5707 -0.078" />
            <geometry>
              <cylinder radius="0.007" length="0.41"/>
            </geometry>
        </collision>

        <collision>
            <origin xyz="0.02 -0.163 0.57" rpy="0 1.5707 0.078" />
            <geometry>
              <cylinder radius="0.007" length="0.41"/>
            </geometry>
        </collision>

        <visual>
            <origin xyz="0 0 0" rpy="0 -0 0" />
            <geometry>
                <mesh filename="package://atlas_description/meshes_v3/utorso_pack.dae" scale="1 1 1" />
            </geometry>
        </visual>
    </link>
    <!-- inertia without backpack
    <link name="utorso">
        <inertial>
            <mass value="22.260" />
            <origin xyz="0.0255 -0.001 0.2180" rpy="0 -0 0" />
            <inertia ixx="0.708" ixy="0.001" ixz="0.004" iyy="0.367" iyz="0.002" izz="0.530" />
        </inertial>
        <visual>
            <origin xyz="0 0 0" rpy="0 -0 0" />
            <geometry>
                <mesh filename="package://atlas_description/meshes_v3/utorso.dae" scale="1 1 1" />
            </geometry>
        </visual>
        <collision>
            <origin xyz="0 0 0" rpy="0 -0 0" />
            <geometry>
                <mesh filename="package://atlas_description/meshes_v3/utorso.stl" scale="1 1 1" />
            </geometry>
        </collision>
        <visual>
            <origin xyz="0 0 0" rpy="0 -0 0" />
            <geometry>
                <mesh filename="package://atlas_description/meshes_v3/utorso_pack.dae" scale="1 1 1" />
            </geometry>
        </visual>
        <collision>
            <origin xyz="0 0 0" rpy="0 -0 0" />
            <geometry>
                <mesh filename="package://atlas_description/meshes_v3/utorso_pack.stl" scale="1 1 1" />
            </geometry>
        </collision>
    </link>
    -->
    <joint name="back_bkx" type="revolute">
        <origin xyz="0 0 0.05" rpy="0 -0 0" />
        <axis xyz="1 0 0" />
        <parent link="mtorso" />
        <child link="utorso" />
        <dynamics damping="0.1" friction="0" />
        <limit effort="200" velocity="12" lower="-0.698132" upper="0.698132" />
        <safety_controller k_position="100" k_velocity="100" soft_lower_limit="-10.6981" soft_upper_limit="10.6981" />
    </joint>
    <joint name="back_bky" type="revolute">
        <origin xyz="0 0 0.16197" rpy="0 -0 0" />
        <axis xyz="0 1 0" />
        <parent link="ltorso" />
        <child link="mtorso" />
        <dynamics damping="0.1" friction="0" />
        <limit effort="206.843" velocity="12" lower="-0.610691" upper="0.438427" />
        <safety_controller k_position="100" k_velocity="100" soft_lower_limit="-10.6107" soft_upper_limit="10.4384" />
    </joint>
    <joint name="back_bkz" type="revolute">
        <origin xyz="-0.0125 0 0" rpy="0 -0 0" />
        <axis xyz="0 0 1" />
        <parent link="pelvis" />
        <child link="ltorso" />
        <dynamics damping="0.2" friction="0" />
        <limit effort="124.016" velocity="12" lower="-0.663225" upper="0.663225" />
        <safety_controller k_position="100" k_velocity="100" soft_lower_limit="-10.6632" soft_upper_limit="10.6632" />
    </joint>
    <joint name="l_arm_elx" type="revolute">
        <origin xyz="0 0.119 0.00921" rpy="0 -0 0" />
        <axis xyz="1 0 0" />
        <parent link="l_uarm" />
        <child link="l_larm" />
        <dynamics damping="0.2" friction="0" />
        <limit effort="114" velocity="12" lower="0" upper="2.35619" />
        <safety_controller k_position="100" k_velocity="100" soft_lower_limit="-10" soft_upper_limit="12.3562" />
    </joint>
    <joint name="l_arm_ely" type="revolute">
        <origin xyz="0 0.187 0.016" rpy="0 -0 0" />
        <axis xyz="0 1 0" />
        <parent link="l_scap" />
        <child link="l_uarm" />
        <dynamics damping="0.1" friction="0" />
        <limit effort="114" velocity="12" lower="0" upper="3.14159" />
        <safety_controller k_position="100" k_velocity="100" soft_lower_limit="-10" soft_upper_limit="13.1416" />
    </joint>
    <joint name="l_arm_shx" type="revolute">
        <origin xyz="0 0.14035 0.19609" rpy="0 -0 0" />
        <axis xyz="1 0 0" />
        <parent link="l_clav" />
        <child link="l_scap" />
        <dynamics damping="0.1" friction="0" />
        <limit effort="170" velocity="12" lower="-1.5708" upper="1.5708" />
        <safety_controller k_position="100" k_velocity="100" soft_lower_limit="-11.5708" soft_upper_limit="11.5708" />
    </joint>
    <joint name="l_arm_shy" type="revolute">
        <origin xyz="0.06441 0.13866 0.10718" rpy="0 -0 0" />
        <axis xyz="0 0.5 0.866025" />
        <parent link="utorso" />
        <child link="l_clav" />
        <dynamics damping="0.1" friction="0" />
        <limit effort="212" velocity="12" lower="-1.5708" upper="0.785398" />
        <safety_controller k_position="100" k_velocity="100" soft_lower_limit="-11.5708" soft_upper_limit="10.7854" />
    </joint>
    <joint name="l_arm_wrx" type="revolute">
        <origin xyz="0 0.119 0.00921" rpy="0 -0 0" />
        <axis xyz="1 0 0" />
        <parent link="l_farm" />
        <child link="l_hand" />
        <dynamics damping="0.1" friction="0" />
        <limit effort="60" velocity="12" lower="-1.1781" upper="1.1781" />
        <safety_controller k_position="100" k_velocity="100" soft_lower_limit="-11.1781" soft_upper_limit="11.1781" />
    </joint>
    <joint name="l_arm_wry" type="revolute">
        <origin xyz="0 0.187 -0.00921" rpy="0 -0 0" />
        <axis xyz="0 1 0" />
        <parent link="l_larm" />
        <child link="l_farm" />
        <dynamics damping="0.1" friction="0" />
        <limit effort="114" velocity="12" lower="0" upper="3.14159" />
        <safety_controller k_position="100" k_velocity="100" soft_lower_limit="-10" soft_upper_limit="13.1416" />
    </joint>
    <joint name="l_leg_akx" type="revolute">
        <origin xyz="0 0 0" rpy="0 -0 0" />
        <axis xyz="1 0 0" />
        <parent link="l_talus" />
        <child link="l_foot" />
        <dynamics damping="0.1" friction="0" />
        <limit effort="90" velocity="12" lower="-0.8" upper="0.8" />
        <safety_controller k_position="100" k_velocity="100" soft_lower_limit="-10.8" soft_upper_limit="10.8" />
    </joint>
    <joint name="l_leg_aky" type="revolute">
        <origin xyz="0 0 -0.422" rpy="0 -0 0" />
        <axis xyz="0 1 0" />
        <parent link="l_lleg" />
        <child link="l_talus" />
        <dynamics damping="0.1" friction="0" />
        <limit effort="700" velocity="12" lower="-1" upper="0.7" />
        <safety_controller k_position="100" k_velocity="100" soft_lower_limit="-11" soft_upper_limit="10.7" />
    </joint>
    <joint name="l_leg_hpx" type="revolute">
        <origin xyz="0 0 0" rpy="0 -0 0" />
        <axis xyz="1 0 0" />
        <parent link="l_uglut" />
        <child link="l_lglut" />
        <dynamics damping="0.1" friction="0" />
        <limit effort="180" velocity="12" lower="-0.523599" upper="0.523599" />
        <safety_controller k_position="100" k_velocity="100" soft_lower_limit="-10.5236" soft_upper_limit="10.5236" />
    </joint>
    <joint name="l_leg_hpy" type="revolute">
        <origin xyz="0.05 0 -0.05" rpy="0 -0 0" />
        <axis xyz="0 1 0" />
        <parent link="l_lglut" />
        <child link="l_uleg" />
        <dynamics damping="0.2" friction="0" />
        <limit effort="260" velocity="12" lower="-1.72072" upper="0.524821" />
        <safety_controller k_position="100" k_velocity="100" soft_lower_limit="-11.7207" soft_upper_limit="10.5248" />
    </joint>
    <joint name="l_leg_hpz" type="revolute">
        <origin xyz="0 0.089 0" rpy="0 -0 0" />
        <axis xyz="0 0 1" />
        <parent link="pelvis" />
        <child link="l_uglut" />
        <dynamics damping="0.1" friction="0" />
        <limit effort="110" velocity="12" lower="-0.174533" upper="1.22173" />
        <safety_controller k_position="100" k_velocity="100" soft_lower_limit="-10.1745" soft_upper_limit="11.2217" />
    </joint>
    <joint name="l_leg_kny" type="revolute">
        <origin xyz="-0.05 0 -0.374" rpy="0 -0 0" />
        <axis xyz="0 1 0" />
        <parent link="l_uleg" />
        <child link="l_lleg" />
        <dynamics damping="0.2" friction="0" />
        <limit effort="220" velocity="12" lower="0" upper="2.38569" />
        <safety_controller k_position="100" k_velocity="100" soft_lower_limit="-10" soft_upper_limit="12.3857" />
    </joint>
    <joint name="neck_ry" type="revolute">
        <origin xyz="0.21672 0 0.53796" rpy="0 -0 0" />
        <axis xyz="0 1 0" />
        <parent link="utorso" />
        <child link="head" />
        <dynamics damping="0.1" friction="0" />
        <limit effort="5" velocity="12" lower="-0.602139" upper="1.14494" />
        <safety_controller k_position="100" k_velocity="100" soft_lower_limit="-10.6021" soft_upper_limit="11.1449" />
    </joint>
    <joint name="r_arm_elx" type="revolute">
        <origin xyz="0 -0.119 0.00921" rpy="0 -0 0" />
        <axis xyz="1 0 0" />
        <parent link="r_uarm" />
        <child link="r_larm" />
        <dynamics damping="0.2" friction="0" />
        <limit effort="114" velocity="12" lower="-2.35619" upper="0" />
        <safety_controller k_position="100" k_velocity="100" soft_lower_limit="-12.3562" soft_upper_limit="10" />
    </joint>
    <joint name="r_arm_ely" type="revolute">
        <origin xyz="0 -0.187 0.016" rpy="0 -0 0" />
        <axis xyz="0 1 0" />
        <parent link="r_scap" />
        <child link="r_uarm" />
        <dynamics damping="0.1" friction="0" />
        <limit effort="114" velocity="12" lower="0" upper="3.14159" />
        <safety_controller k_position="100" k_velocity="100" soft_lower_limit="-10" soft_upper_limit="13.1416" />
    </joint>
    <joint name="r_arm_shx" type="revolute">
        <origin xyz="0 -0.14035 0.19609" rpy="0 -0 0" />
        <axis xyz="1 0 0" />
        <parent link="r_clav" />
        <child link="r_scap" />
        <dynamics damping="0.1" friction="0" />
        <limit effort="170" velocity="12" lower="-1.5708" upper="1.5708" />
        <safety_controller k_position="100" k_velocity="100" soft_lower_limit="-11.5708" soft_upper_limit="11.5708" />
    </joint>
    <joint name="r_arm_shy" type="revolute">
        <origin xyz="0.06441 -0.13866 0.10718" rpy="0 -0 0" />
        <axis xyz="0 0.5 -0.866025" />
        <parent link="utorso" />
        <child link="r_clav" />
        <dynamics damping="0.1" friction="0" />
        <limit effort="212" velocity="12" lower="-1.5708" upper="0.785398" />
        <safety_controller k_position="100" k_velocity="100" soft_lower_limit="-11.5708" soft_upper_limit="10.7854" />
    </joint>
    <joint name="r_arm_wrx" type="revolute">
        <origin xyz="0 -0.119 0.00921" rpy="0 -0 0" />
        <axis xyz="1 0 0" />
        <parent link="r_farm" />
        <child link="r_hand" />
        <dynamics damping="0.1" friction="0" />
        <limit effort="60" velocity="12" lower="-1.1781" upper="1.1781" />
        <safety_controller k_position="100" k_velocity="100" soft_lower_limit="-11.1781" soft_upper_limit="11.1781" />
    </joint>
    <joint name="r_arm_wry" type="revolute">
        <origin xyz="0 -0.187 -0.00921" rpy="0 -0 0" />
        <axis xyz="0 1 0" />
        <parent link="r_larm" />
        <child link="r_farm" />
        <dynamics damping="0.1" friction="0" />
        <limit effort="114" velocity="12" lower="0" upper="3.14159" />
        <safety_controller k_position="100" k_velocity="100" soft_lower_limit="-10" soft_upper_limit="13.1416" />
    </joint>
    <joint name="r_leg_akx" type="revolute">
        <origin xyz="0 0 0" rpy="0 -0 0" />
        <axis xyz="1 0 0" />
        <parent link="r_talus" />
        <child link="r_foot" />
        <dynamics damping="0.1" friction="0" />
        <limit effort="90" velocity="12" lower="-0.8" upper="0.8" />
        <safety_controller k_position="100" k_velocity="100" soft_lower_limit="-10.8" soft_upper_limit="10.8" />
    </joint>
    <joint name="r_leg_aky" type="revolute">
        <origin xyz="0 0 -0.422" rpy="0 -0 0" />
        <axis xyz="0 1 0" />
        <parent link="r_lleg" />
        <child link="r_talus" />
        <dynamics damping="0.1" friction="0" />
        <limit effort="700" velocity="12" lower="-1" upper="0.7" />
        <safety_controller k_position="100" k_velocity="100" soft_lower_limit="-11" soft_upper_limit="10.7" />
    </joint>
    <joint name="r_leg_hpx" type="revolute">
        <origin xyz="0 0 0" rpy="0 -0 0" />
        <axis xyz="1 0 0" />
        <parent link="r_uglut" />
        <child link="r_lglut" />
        <dynamics damping="0.1" friction="0" />
        <limit effort="180" velocity="12" lower="-0.523599" upper="0.523599" />
        <safety_controller k_position="100" k_velocity="100" soft_lower_limit="-10.5236" soft_upper_limit="10.5236" />
    </joint>
    <joint name="r_leg_hpy" type="revolute">
        <origin xyz="0.05 0 -0.05" rpy="0 -0 0" />
        <axis xyz="0 1 0" />
        <parent link="r_lglut" />
        <child link="r_uleg" />
        <dynamics damping="0.2" friction="0" />
        <limit effort="260" velocity="12" lower="-1.72072" upper="0.524821" />
        <safety_controller k_position="100" k_velocity="100" soft_lower_limit="-11.7207" soft_upper_limit="10.5248" />
    </joint>
    <joint name="r_leg_hpz" type="revolute">
        <origin xyz="0 -0.089 0" rpy="0 -0 0" />
        <axis xyz="0 0 1" />
        <parent link="pelvis" />
        <child link="r_uglut" />
        <dynamics damping="0.1" friction="0" />
        <limit effort="110" velocity="12" lower="-1.22173" upper="0.174533" />
        <safety_controller k_position="100" k_velocity="100" soft_lower_limit="-11.2217" soft_upper_limit="10.1745" />
    </joint>
    <joint name="r_leg_kny" type="revolute">
        <origin xyz="-0.05 0 -0.374" rpy="0 -0 0" />
        <axis xyz="0 1 0" />
        <parent link="r_uleg" />
        <child link="r_lleg" />
        <dynamics damping="0.2" friction="0" />
        <limit effort="220" velocity="12" lower="0" upper="2.38569" />
        <safety_controller k_position="100" k_velocity="100" soft_lower_limit="-10" soft_upper_limit="12.3857" />
    </joint>

    <!-- new situational awareness cameras -->
    <link name="r_situational_awareness_camera_link">
      <inertial>
        <mass value="0.1"/>
        <origin xyz="0 0 0"/>
        <inertia ixx="0.00001" ixy="0" ixz="0" iyy="0.00001" iyz="0" izz="0.00001"/>
      </inertial>
      <visual>
        <origin rpy="0 0 0" xyz="0 0 0"/>
        <geometry>
          <box size="0.01 0.01 0.01"/>
        </geometry>
      </visual>
    </link>
    <joint name="r_situational_awareness_camera_joint" type="fixed">
      <parent link="utorso"/>
      <child link="r_situational_awareness_camera_link"/>
      <!-- if camera points x-forward, bottom towards front of robot, 15 degree yaw forwards from
           lateral (+y) view -->
      <origin xyz="0.216409 -0.121799 0.406759" rpy="1.57079633 0 -1.30899694"/>
    </joint>
    <joint name="r_situational_awareness_camera_optical_frame_joint" type="fixed">
      <origin xyz="0 0 0" rpy="-1.5708 0.0 -1.5708" />
      <parent link="r_situational_awareness_camera_link" />
      <child link="r_situational_awareness_camera_optical_frame"/>
    </joint>
    <link name="r_situational_awareness_camera_optical_frame"/>

    <link name="l_situational_awareness_camera_link">
      <inertial>
        <mass value="0.1"/>
        <origin xyz="0 0 0"/>
        <inertia ixx="0.00001" ixy="0" ixz="0" iyy="0.00001" iyz="0" izz="0.00001"/>
      </inertial>
      <visual>
        <origin rpy="0 0 0" xyz="0 0 0"/>
        <geometry>
          <box size="0.01 0.01 0.01"/>
        </geometry>
      </visual>
    </link>
    <joint name="l_situational_awareness_camera_joint" type="fixed">
      <parent link="utorso"/>
      <child link="l_situational_awareness_camera_link"/>
      <!-- if camera points x-forward, bottom towards front of robot, 15 degree yaw forwards from
           lateral (+y) view -->
      <origin xyz="0.216409 0.121799 0.406759" rpy="-1.57079633 0 1.30899694"/>
    </joint>
    <joint name="l_situational_awareness_camera_optical_frame_joint" type="fixed">
      <origin xyz="0 0 0" rpy="-1.5708 0.0 -1.5708" />
      <parent link="l_situational_awareness_camera_link" />
      <child link="l_situational_awareness_camera_optical_frame"/>
    </joint>
    <link name="l_situational_awareness_camera_optical_frame"/>

    <link name="rear_situational_awareness_camera_link">
      <inertial>
        <mass value="0.1"/>
        <origin xyz="0 0 0"/>
        <inertia ixx="0.00001" ixy="0" ixz="0" iyy="0.00001" iyz="0" izz="0.00001"/>
      </inertial>
      <visual>
        <origin rpy="0 0 0" xyz="0 0 0"/>
        <geometry>
          <box size="0.01 0.01 0.01"/>
        </geometry>
      </visual>
    </link>
    <joint name="rear_situational_awareness_camera_joint" type="fixed">
      <parent link="utorso"/>
      <child link="rear_situational_awareness_camera_link"/>
      <!-- if camera points towards -X direction of the utorso link frame -->
      <origin xyz="-0.0026 0.0264 0.6649" rpy="0 0 3.14159"/>
    </joint>
    <joint name="rear_situational_awareness_camera_optical_frame_joint" type="fixed">
      <origin xyz="0 0 0" rpy="-1.5708 0.0 -1.5708" />
      <parent link="rear_situational_awareness_camera_link" />
      <child link="rear_situational_awareness_camera_optical_frame"/>
    </joint>
    <link name="rear_situational_awareness_camera_optical_frame"/>

</robot>
