<?xml version="1.0" ?>
<!-- =================================================================================== -->
<!-- |    This document was autogenerated by xacro from ../../SDK/urdf/minitaur_original.urdf.xacro | -->
<!-- |    EDITING THIS FILE BY HAND IS NOT RECOMMENDED                                 | -->
<!-- =================================================================================== -->
<!-- ======================================================================= -->
<!--LICENSE:                                                                 -->
<!--Copyright (c) 2017, Erwin Coumans                                        -->
<!--Google Inc.                                                              -->
<!--All rights reserved.                                                     -->
<!--                                                                         -->
<!--Redistribution and use in source and binary forms, with or without       -->
<!--modification, are permitted provided that the following conditions are   -->
<!--met:                                                                     -->
<!--                                                                         -->
<!--1. Redistributions or derived work must retain this copyright notice,    -->
<!--   this list of conditions and the following disclaimer.                 -->
<!--                                                                         -->
<!--2. Redistributions in binary form must reproduce the above copyright     -->
<!--   notice, this list of conditions and the following disclaimer in the   -->
<!--   documentation and/or other materials provided with the distribution.  -->
<!--                                                                         -->
<!--THIS SOFTWARE IS PROVIDED BY THE COPYRIGHT HOLDERS AND CONTRIBUTORS "AS  -->
<!--IS" AND ANY EXPRESS OR IMPLIED WARRANTIES, INCLUDING, BUT NOT LIMITED TO,-->
<!--THE IMPLIED WARRANTIES OF MERCHANTABILITY AND FITNESS FOR A PARTICULAR   -->
<!--PURPOSE ARE DISCLAIMED. IN NO EVENT SHALL THE COPYRIGHT HOLDER OR        -->
<!--CONTRIBUTORS BE LIABLE FOR ANY DIRECT, INDIRECT, INCIDENTAL, SPECIAL,    -->
<!--EXEMPLARY, OR CONSEQUENTIAL DAMAGES (INCLUDING, BUT NOT LIMITED TO,      -->
<!--PROCUREMENT OF SUBSTITUTE GOODS OR SERVICES; LOSS OF USE, DATA, OR       -->
<!--PROFITS; OR BUSINESS INTERRUPTION) HOWEVER CAUSED AND ON ANY THEORY OF   -->
<!--LIABILITY, WHETHER IN CONTRACT, STRICT LIABILITY, OR TORT (INCLUDING     -->
<!--NEGLIGENCE OR OTHERWISE) ARISING IN ANY WAY OUT OF THE USE OF THIS       -->
<!--SOFTWARE, EVEN IF ADVISED OF THE POSSIBILITY OF SUCH DAMAGE.             -->
<!--                                                                         -->
<!-- Converted to xacro by Tom Jacobs <tom.jacobs@ghostrobotics.io>          -->
<robot name="minitaur" xmlns:xacro="http://www.ros.org/wiki/xacro">
    <!-- Define parameters -->
    <!-- 7.18kg minitaur total weight - 0.016*4 - 0.10*8 - 0.25*8 - 0.05*8 - 0.05*8 = 3.516 -->
    <!-- * 4 frames -->
    <!-- * 8 motor modules -->
    <!-- * 8 motors -->
    <!-- * 8 upper legs -->
    <!-- * 8 lower legs -->
    <!-- Define materials -->
    <material name="black">
        <color rgba="0.3 0.3 0.3 1"/>
    </material>
    <material name="grey">
        <color rgba="0.5 0.5 0.5 1"/>
    </material>
    <material name="frameGrey">
        <color rgba="0.55 0.55 0.55 1"/>
    </material>
    <material name="legGrey">
        <color rgba="0.65 0.65 0.75 1"/>
    </material>
    <material name="motor">
        <color rgba="0.2 0.2 0.2 1"/>
    </material>
    <!-- Body -->
    <link name="base_chassis_link">
        <visual>
            <geometry>
                <box size="0.33 0.1855 0.08"/>
            </geometry>
            <material name="black"/>
        </visual>
        <visual>
            <origin rpy="0 0 0" xyz="0 0.10 -0.014"/>
            <geometry>
                <box size="0.17 0.1 0.05"/>
            </geometry>
            <material name="black"/>
        </visual>
        <visual>
            <origin rpy="0 0 0" xyz="0 -0.10 -0.014"/>
            <geometry>
                <box size="0.17 0.1 0.05"/>
            </geometry>
            <material name="black"/>
        </visual>
        <collision>
            <geometry>
                <box size="0.33 0.1855 0.08"/>
            </geometry>
        </collision>
        <collision>
            <origin rpy="0 0 0" xyz="0 0.10 -0.014"/>
            <geometry>
                <box size="0.17 0.1 0.05"/>
            </geometry>
        </collision>
        <collision>
            <origin rpy="0 0 0" xyz="0 -0.10 -0.014"/>
            <geometry>
                <box size="0.17 0.1 0.05"/>
            </geometry>
        </collision>
        <inertial>
            <origin xyz="-0.000001 -0.001048 -0.005376" quat="0.000000 0.000000 0.000000 1.000000"/>
            <mass value="4.9559989"/>
            <!-- https://en.wikipedia.org/wiki/List_of_moments_of_inertia Solid Cuboid -->
            <inertia ixx="0.061256915" ixy="-1.6763806e-08" ixz="-5.1921234e-08" iyy="0.17553288" iyz="-6.8246009e-05" izz="0.22581783"/>
        </inertial>
        <collision>
            <origin xyz="-0.237500 0.174000 -0.018500" quat="0.000000 0.000000 0.000000 1.000000"/>
            <geometry>
                <box size=".068 .032 .050"/>
            </geometry>
        </collision>
        <visual>
            <origin xyz="-0.237500 0.174000 -0.018500" quat="0.000000 0.000000 0.000000 1.000000"/>
            <geometry>
                <box size="0.068 .032 .050"/>
            </geometry>
            <material name="motor"/>
        </visual>
        <collision>
            <origin xyz="-0.237500 -0.174000 -0.018500" quat="0.000000 0.000000 0.000000 1.000000"/>
            <geometry>
                <box size=".068 .032 .050"/>
            </geometry>
        </collision>
        <visual>
            <origin xyz="-0.237500 -0.174000 -0.018500" quat="0.000000 0.000000 0.000000 1.000000"/>
            <geometry>
                <box size="0.068 .032 .050"/>
            </geometry>
            <material name="motor"/>
        </visual>
        <collision>
            <origin xyz="0.237500 0.174000 -0.018500" quat="0.000000 0.000000 0.000000 1.000000"/>
            <geometry>
                <box size=".068 .032 .050"/>
            </geometry>
        </collision>
        <visual>
            <origin xyz="0.237500 0.174000 -0.018500" quat="0.000000 0.000000 0.000000 1.000000"/>
            <geometry>
                <box size="0.068 .032 .050"/>
            </geometry>
            <material name="motor"/>
        </visual>
        <collision>
            <origin xyz="0.237500 -0.174000 -0.018500" quat="0.000000 0.000000 0.000000 1.000000"/>
            <geometry>
                <box size=".068 .032 .050"/>
            </geometry>
        </collision>
        <visual>
            <origin xyz="0.237500 -0.174000 -0.018500" quat="0.000000 0.000000 0.000000 1.000000"/>
            <geometry>
                <box size="0.068 .032 .050"/>
            </geometry>
            <material name="motor"/>
        </visual>
        <collision>
            <origin xyz="0.237500 0.072500 -0.018500" quat="0.000000 0.000000 0.000000 1.000000"/>
            <geometry>
                <box size=".068 .032 .050"/>
            </geometry>
        </collision>
        <collision>
            <origin xyz="-0.237500 0.072500 -0.018500" quat="0.000000 0.000000 0.000000 1.000000"/>
            <geometry>
                <box size=".068 .032 .050"/>
            </geometry>
        </collision>
        <visual>
            <origin xyz="0.237500 0.072500 -0.018500" quat="0.000000 0.000000 0.000000 1.000000"/>
            <geometry>
                <box size=".068 .032 .050"/>
            </geometry>
            <material name="motor"/>
        </visual>
        <visual>
            <origin xyz="-0.237500 0.072500 -0.018500" quat="0.000000 0.000000 0.000000 1.000000"/>
            <geometry>
                <box size=".068 .032 .050"/>
            </geometry>
            <material name="motor"/>
        </visual>
        <collision>
            <origin xyz="0.237500 -0.072500 -0.018500" quat="0.000000 0.000000 0.000000 1.000000"/>
            <geometry>
                <box size=".068 .032 .050"/>
            </geometry>
        </collision>
        <collision>
            <origin xyz="-0.237500 -0.072500 -0.018500" quat="0.000000 0.000000 0.000000 1.000000"/>
            <geometry>
                <box size=".068 .032 .050"/>
            </geometry>
        </collision>
        <visual>
            <origin xyz="0.237500 -0.072500 -0.018500" quat="0.000000 0.000000 0.000000 1.000000"/>
            <geometry>
                <box size=".068 .032 .050"/>
            </geometry>
            <material name="motor"/>
        </visual>
        <visual>
            <origin xyz="-0.237500 -0.072500 -0.018500" quat="0.000000 0.000000 0.000000 1.000000"/>
            <geometry>
                <box size=".068 .032 .050"/>
            </geometry>
            <material name="motor"/>
        </visual>
        <collision>
            <origin xyz="-0.017500 0.099000 -0.018500" quat="0.000000 0.000000 0.000000 1.000000"/>
            <geometry>
                <box size="0.468 .012 .050"/>
            </geometry>
        </collision>
        <visual>
            <origin xyz="-0.017500 0.099000 -0.018500" quat="0.000000 0.000000 0.000000 1.000000"/>
            <geometry>
                <box size="0.468 .012 .050"/>
            </geometry>
            <material name="frameGrey"/>
        </visual>
        <collision>
            <origin xyz="-0.017500 -0.099000 -0.018500" quat="0.000000 0.000000 0.000000 1.000000"/>
            <geometry>
                <box size="0.468 .012 .050"/>
            </geometry>
        </collision>
        <visual>
            <origin xyz="-0.017500 -0.099000 -0.018500" quat="0.000000 0.000000 0.000000 1.000000"/>
            <geometry>
                <box size="0.468 .012 .050"/>
            </geometry>
            <material name="frameGrey"/>
        </visual>
        <collision>
            <origin xyz="0.017500 0.154000 -0.018500" quat="0.000000 0.000000 0.000000 1.000000"/>
            <geometry>
                <box size="0.468 .012 .050"/>
            </geometry>
        </collision>
        <visual>
            <origin xyz="0.017500 0.154000 -0.018500" quat="0.000000 0.000000 0.000000 1.000000"/>
            <geometry>
                <box size="0.468 .012 .050"/>
            </geometry>
            <material name="frameGrey"/>
        </visual>
        <collision>
            <origin xyz="0.017500 -0.154000 -0.018500" quat="0.000000 0.000000 0.000000 1.000000"/>
            <geometry>
                <box size="0.468 .012 .050"/>
            </geometry>
        </collision>
        <visual>
            <origin xyz="0.017500 -0.154000 -0.018500" quat="0.000000 0.000000 0.000000 1.000000"/>
            <geometry>
                <box size="0.468 .012 .050"/>
            </geometry>
            <material name="frameGrey"/>
        </visual>
    </link>
    <!-- Frame -->
    <!-- Inside motor module boxes -->
    <!-- Outside motor module boxes -->
    <!-- Define our motor macro -->
    <!-- Motors -->
    <link name="motor_front_rightR_link">
        <visual>
            <geometry>
                <mesh filename="tmotor3.obj" scale="1.0 1.0 1.0"/>
            </geometry>
            <material name="motor"/>
        </visual>
        <collision>
            <geometry>
                <cylinder length="0.021" radius="0.0425"/>
            </geometry>
        </collision>
        <inertial>
            <origin xyz="0.000000 0.007500 -0.002417" quat="0.000000 0.000000 0.000000 1.000000"/>
            <mass value="0.30000001"/>
            <inertia ixx="0.00024587542" ixy="0" ixz="0" iyy="0.00012633341" iyz="2.7185712e-05" izz="0.00034422299"/>
        </inertial>
        <collision>
            <origin xyz="0.000000 0.045000 -0.014500" quat="-0.707090 0.000000 0.000000 0.707123"/>
            <geometry>
                <box size="0.039 0.008 0.1"/>
            </geometry>
        </collision>
        <visual>
            <origin xyz="0.000000 0.045000 -0.014500" quat="-0.707090 0.000000 0.000000 0.707123"/>
            <geometry>
                <box size="0.039 0.008 0.1"/>
            </geometry>
            <material name="legGrey"/>
        </visual>
    </link>
    <joint name="5" type="continuous">
        <axis xyz="0 0 1"/>
        <parent link="base_chassis_link"/>
        <child link="motor_front_rightR_link"/>
        <origin xyz="0.237500 -0.154000 -0.018500" quat="0.707090 0.000000 0.000000 0.707123"/>
        <limit effort="100" velocity="100"/>
        <joint_properties damping="0.0" friction="0.0"/>
    </joint>
    <link name="motor_front_rightL_link">
        <visual>
            <geometry>
                <mesh filename="tmotor3.obj" scale="1.0 1.0 1.0"/>
            </geometry>
            <material name="motor"/>
        </visual>
        <collision>
            <geometry>
                <cylinder length="0.021" radius="0.0425"/>
            </geometry>
        </collision>
        <inertial>
            <origin xyz="0.000000 0.007500 -0.002417" quat="0.000000 0.000000 0.000000 1.000000"/>
            <mass value="0.30000001"/>
            <inertia ixx="0.00024587542" ixy="0" ixz="0" iyy="0.00012633341" iyz="2.7185712e-05" izz="0.00034422299"/>
        </inertial>
        <collision>
            <origin xyz="0.000000 0.045000 -0.014500" quat="-0.707090 0.000000 0.000000 0.707123"/>
            <geometry>
                <box size="0.039 0.008 0.1"/>
            </geometry>
        </collision>
        <visual>
            <origin xyz="0.000000 0.045000 -0.014500" quat="-0.707090 0.000000 0.000000 0.707123"/>
            <geometry>
                <box size="0.039 0.008 0.1"/>
            </geometry>
            <material name="legGrey"/>
        </visual>
    </link>
    <joint name="4" type="continuous">
        <axis xyz="0 0 1"/>
        <parent link="base_chassis_link"/>
        <child link="motor_front_rightL_link"/>
        <origin xyz="0.237500 -0.099000 -0.018500" quat="0.000000 0.707090 0.707123 0.000000"/>
        <limit effort="100" velocity="100"/>
        <joint_properties damping="0.0" friction="0.0"/>
    </joint>
    <link name="motor_front_leftL_link">
        <visual>
            <geometry>
                <mesh filename="tmotor3.obj" scale="1.0 1.0 1.0"/>
            </geometry>
            <material name="motor"/>
        </visual>
        <collision>
            <geometry>
                <cylinder length="0.021" radius="0.0425"/>
            </geometry>
        </collision>
        <inertial>
            <origin xyz="0.000000 0.007500 -0.002417" quat="0.000000 0.000000 0.000000 1.000000"/>
            <mass value="0.30000001"/>
            <inertia ixx="0.00024587542" ixy="0" ixz="0" iyy="0.00012633341" iyz="2.7185712e-05" izz="0.00034422299"/>
        </inertial>
        <collision>
            <origin xyz="0.000000 0.045000 -0.014500" quat="-0.707090 0.000000 0.000000 0.707123"/>
            <geometry>
                <box size="0.039 0.008 0.1"/>
            </geometry>
        </collision>
        <visual>
            <origin xyz="0.000000 0.045000 -0.014500" quat="-0.707090 0.000000 0.000000 0.707123"/>
            <geometry>
                <box size="0.039 0.008 0.1"/>
            </geometry>
            <material name="legGrey"/>
        </visual>
    </link>
    <joint name="0" type="continuous">
        <axis xyz="0 0 1"/>
        <parent link="base_chassis_link"/>
        <child link="motor_front_leftL_link"/>
        <origin xyz="0.237500 0.154000 -0.018500" quat="0.000000 0.707090 0.707123 0.000000"/>
        <limit effort="100" velocity="100"/>
        <joint_properties damping="0.0" friction="0.0"/>
    </joint>
    <link name="motor_front_leftR_link">
        <visual>
            <geometry>
                <mesh filename="tmotor3.obj" scale="1.0 1.0 1.0"/>
            </geometry>
            <material name="motor"/>
        </visual>
        <collision>
            <geometry>
                <cylinder length="0.021" radius="0.0425"/>
            </geometry>
        </collision>
        <inertial>
            <origin xyz="0.000000 0.007500 -0.002417" quat="0.000000 0.000000 0.000000 1.000000"/>
            <mass value="0.30000001"/>
            <inertia ixx="0.00024587542" ixy="0" ixz="0" iyy="0.00012633341" iyz="2.7185712e-05" izz="0.00034422299"/>
        </inertial>
        <collision>
            <origin xyz="0.000000 0.045000 -0.014500" quat="-0.707090 0.000000 0.000000 0.707123"/>
            <geometry>
                <box size="0.039 0.008 0.1"/>
            </geometry>
        </collision>
        <visual>
            <origin xyz="0.000000 0.045000 -0.014500" quat="-0.707090 0.000000 0.000000 0.707123"/>
            <geometry>
                <box size="0.039 0.008 0.1"/>
            </geometry>
            <material name="legGrey"/>
        </visual>
    </link>
    <joint name="1" type="continuous">
        <axis xyz="0 0 1"/>
        <parent link="base_chassis_link"/>
        <child link="motor_front_leftR_link"/>
        <origin xyz="0.237500 0.099000 -0.018500" quat="0.707090 0.000000 0.000000 0.707123"/>
        <limit effort="100" velocity="100"/>
        <joint_properties damping="0.0" friction="0.0"/>
    </joint>
    <link name="motor_back_rightR_link">
        <visual>
            <geometry>
                <mesh filename="tmotor3.obj" scale="1.0 1.0 1.0"/>
            </geometry>
            <material name="motor"/>
        </visual>
        <collision>
            <geometry>
                <cylinder length="0.021" radius="0.0425"/>
            </geometry>
        </collision>
        <inertial>
            <origin xyz="0.000000 0.007500 -0.002417" quat="0.000000 0.000000 0.000000 1.000000"/>
            <mass value="0.30000001"/>
            <inertia ixx="0.00024587542" ixy="0" ixz="0" iyy="0.00012633341" iyz="2.7185712e-05" izz="0.00034422299"/>
        </inertial>
        <collision>
            <origin xyz="0.000000 0.045000 -0.014500" quat="-0.707090 0.000000 0.000000 0.707123"/>
            <geometry>
                <box size="0.039 0.008 0.1"/>
            </geometry>
        </collision>
        <visual>
            <origin xyz="0.000000 0.045000 -0.014500" quat="-0.707090 0.000000 0.000000 0.707123"/>
            <geometry>
                <box size="0.039 0.008 0.1"/>
            </geometry>
            <material name="legGrey"/>
        </visual>
    </link>
    <joint name="7" type="continuous">
        <axis xyz="0 0 1"/>
        <parent link="base_chassis_link"/>
        <child link="motor_back_rightR_link"/>
        <origin xyz="-0.237500 -0.154000 -0.018500" quat="0.707090 0.000000 0.000000 0.707123"/>
        <limit effort="100" velocity="100"/>
        <joint_properties damping="0.0" friction="0.0"/>
    </joint>
    <link name="motor_back_rightL_link">
        <visual>
            <geometry>
                <mesh filename="tmotor3.obj" scale="1.0 1.0 1.0"/>
            </geometry>
            <material name="motor"/>
        </visual>
        <collision>
            <geometry>
                <cylinder length="0.021" radius="0.0425"/>
            </geometry>
        </collision>
        <inertial>
            <origin xyz="0.000000 0.007500 -0.002417" quat="0.000000 0.000000 0.000000 1.000000"/>
            <mass value="0.30000001"/>
            <inertia ixx="0.00024587542" ixy="0" ixz="0" iyy="0.00012633341" iyz="2.7185712e-05" izz="0.00034422299"/>
        </inertial>
        <collision>
            <origin xyz="0.000000 0.045000 -0.014500" quat="-0.707090 0.000000 0.000000 0.707123"/>
            <geometry>
                <box size="0.039 0.008 0.1"/>
            </geometry>
        </collision>
        <visual>
            <origin xyz="0.000000 0.045000 -0.014500" quat="-0.707090 0.000000 0.000000 0.707123"/>
            <geometry>
                <box size="0.039 0.008 0.1"/>
            </geometry>
            <material name="legGrey"/>
        </visual>
    </link>
    <joint name="6" type="continuous">
        <axis xyz="0 0 1"/>
        <parent link="base_chassis_link"/>
        <child link="motor_back_rightL_link"/>
        <origin xyz="-0.237500 -0.099000 -0.018500" quat="0.000000 0.707090 0.707123 0.000000"/>
        <limit effort="100" velocity="100"/>
        <joint_properties damping="0.0" friction="0.0"/>
    </joint>
    <link name="motor_back_leftL_link">
        <visual>
            <geometry>
                <mesh filename="tmotor3.obj" scale="1.0 1.0 1.0"/>
            </geometry>
            <material name="motor"/>
        </visual>
        <collision>
            <geometry>
                <cylinder length="0.021" radius="0.0425"/>
            </geometry>
        </collision>
        <inertial>
            <origin xyz="0.000000 0.007500 -0.002417" quat="0.000000 0.000000 0.000000 1.000000"/>
            <mass value="0.30000001"/>
            <inertia ixx="0.00024587542" ixy="0" ixz="0" iyy="0.00012633341" iyz="2.7185712e-05" izz="0.00034422299"/>
        </inertial>
        <collision>
            <origin xyz="0.000000 0.045000 -0.014500" quat="-0.707090 0.000000 0.000000 0.707123"/>
            <geometry>
                <box size="0.039 0.008 0.1"/>
            </geometry>
        </collision>
        <visual>
            <origin xyz="0.000000 0.045000 -0.014500" quat="-0.707090 0.000000 0.000000 0.707123"/>
            <geometry>
                <box size="0.039 0.008 0.1"/>
            </geometry>
            <material name="legGrey"/>
        </visual>
    </link>
    <joint name="2" type="continuous">
        <axis xyz="0 0 1"/>
        <parent link="base_chassis_link"/>
        <child link="motor_back_leftL_link"/>
        <origin xyz="-0.237500 0.154000 -0.018500" quat="0.000000 0.707090 0.707123 0.000000"/>
        <limit effort="100" velocity="100"/>
        <joint_properties damping="0.0" friction="0.0"/>
    </joint>
    <link name="motor_back_leftR_link">
        <visual>
            <geometry>
                <mesh filename="tmotor3.obj" scale="1.0 1.0 1.0"/>
            </geometry>
            <material name="motor"/>
        </visual>
        <collision>
            <geometry>
                <cylinder length="0.021" radius="0.0425"/>
            </geometry>
        </collision>
        <inertial>
            <origin xyz="0.000000 0.007500 -0.002417" quat="0.000000 0.000000 0.000000 1.000000"/>
            <mass value="0.30000001"/>
            <inertia ixx="0.00024587542" ixy="0" ixz="0" iyy="0.00012633341" iyz="2.7185712e-05" izz="0.00034422299"/>
        </inertial>
        <collision>
            <origin xyz="0.000000 0.045000 -0.014500" quat="-0.707090 0.000000 0.000000 0.707123"/>
            <geometry>
                <box size="0.039 0.008 0.1"/>
            </geometry>
        </collision>
        <visual>
            <origin xyz="0.000000 0.045000 -0.014500" quat="-0.707090 0.000000 0.000000 0.707123"/>
            <geometry>
                <box size="0.039 0.008 0.1"/>
            </geometry>
            <material name="legGrey"/>
        </visual>
    </link>
    <joint name="3" type="continuous">
        <axis xyz="0 0 1"/>
        <parent link="base_chassis_link"/>
        <child link="motor_back_leftR_link"/>
        <origin xyz="-0.237500 0.099000 -0.018500" quat="0.707090 0.000000 0.000000 0.707123"/>
        <limit effort="100" velocity="100"/>
        <joint_properties damping="0.0" friction="0.0"/>
    </joint>
    <!-- Define our upper leg macro -->
    <!-- Define our lower leg macro -->
    <!-- Legs -->
    <!-- Lower legs and flexy knee joints -->
    <link name="lower_leg_front_rightR_link">
        <contact>
            <friction_anchor/>
            <stiffness value="3000.0"/>
            <damping value="100.0"/>
            <spinning_friction value=".05"/>
            <lateral_friction value="1"/>
        </contact>
        <visual>
            <origin rpy="0 0 0" xyz="0 0 0.124"/>
            <geometry>
                <box size="0.017 0.009 0.248"/>
            </geometry>
            <material name="legGrey"/>
        </visual>
        <collision>
            <origin rpy="0 0 0" xyz="0 0 0.124"/>
            <geometry>
                <box size="0.017 0.009 0.248"/>
            </geometry>
        </collision>
        <inertial>
            <origin xyz="0.000000 0.000000 0.144667" quat="0.000000 0.000000 0.000000 1.000000"/>
            <mass value="0.060000002"/>
            <inertia ixx="0.00047772331" ixy="0" ixz="0" iyy="0.00047950333" iyz="0" izz="2.7177999e-05"/>
        </inertial>
        <collision>
            <origin xyz="0.000000 0.000000 0.248000" quat="0.000000 0.000000 0.000000 1.000000"/>
            <geometry>
                <sphere radius="0.015"/>
            </geometry>
        </collision>
        <visual>
            <origin xyz="0.000000 0.000000 0.248000" quat="0.000000 0.000000 0.000000 1.000000"/>
            <geometry>
                <sphere radius="0.015"/>
            </geometry>
            <material name="black"/>
        </visual>
    </link>
    <joint name="8" type="continuous">
        <axis xyz="0 1 0"/>
        <parent link="motor_front_rightR_link"/>
        <child link="lower_leg_front_rightR_link"/>
        <origin xyz="0.000000 0.095000 -0.022998" quat="-0.707090 0.000000 0.000000 0.707123"/>
        <limit effort="100" velocity="100"/>
        <joint_properties damping="0.0" friction="0.0"/>
    </joint>
    <!-- Toe -->
    <link name="lower_leg_front_rightL_link">
        <contact>
            <friction_anchor/>
            <stiffness value="3000.0"/>
            <damping value="100.0"/>
            <spinning_friction value=".05"/>
            <lateral_friction value="1"/>
        </contact>
        <visual>
            <origin rpy="0 0 0" xyz="0 0 0.1"/>
            <geometry>
                <box size="0.017 0.009 0.2"/>
            </geometry>
            <material name="legGrey"/>
        </visual>
        <collision>
            <origin rpy="0 0 0" xyz="0 0 0.1"/>
            <geometry>
                <box size="0.017 0.009 0.2"/>
            </geometry>
        </collision>
        <inertial>
            <origin rpy="0 0 0" xyz="0 0 0.1"/>
            <mass value="0.05"/>
            <inertia ixx=".00032459" ixy=".0" ixz=".0" iyy=".00032637" iyz=".0" izz=".000002178"/>
        </inertial>
    </link>
    <joint name="9" type="continuous">
        <axis xyz="0 1 0"/>
        <parent link="motor_front_rightL_link"/>
        <child link="lower_leg_front_rightL_link"/>
        <origin xyz="0.000000 0.095000 -0.022998" quat="-0.707090 0.000000 0.000000 0.707123"/>
        <limit effort="100" velocity="100"/>
        <joint_properties damping="0.0" friction="0.0"/>
    </joint>
    <link name="lower_leg_front_leftR_link">
        <contact>
            <friction_anchor/>
            <stiffness value="3000.0"/>
            <damping value="100.0"/>
            <spinning_friction value=".05"/>
            <lateral_friction value="1"/>
        </contact>
        <visual>
            <origin rpy="0 0 0" xyz="0 0 0.1"/>
            <geometry>
                <box size="0.017 0.009 0.2"/>
            </geometry>
            <material name="legGrey"/>
        </visual>
        <collision>
            <origin rpy="0 0 0" xyz="0 0 0.1"/>
            <geometry>
                <box size="0.017 0.009 0.2"/>
            </geometry>
        </collision>
        <inertial>
            <origin rpy="0 0 0" xyz="0 0 0.1"/>
            <mass value="0.05"/>
            <inertia ixx=".00032459" ixy=".0" ixz=".0" iyy=".00032637" iyz=".0" izz=".000002178"/>
        </inertial>
    </link>
    <joint name="11" type="continuous">
        <axis xyz="0 1 0"/>
        <parent link="motor_front_leftR_link"/>
        <child link="lower_leg_front_leftR_link"/>
        <origin xyz="0.000000 0.095000 -0.022998" quat="-0.707090 0.000000 0.000000 0.707123"/>
        <limit effort="100" velocity="100"/>
        <joint_properties damping="0.0" friction="0.0"/>
    </joint>
    <link name="lower_leg_front_leftL_link">
        <contact>
            <friction_anchor/>
            <stiffness value="3000.0"/>
            <damping value="100.0"/>
            <spinning_friction value=".05"/>
            <lateral_friction value="1"/>
        </contact>
        <visual>
            <origin rpy="0 0 0" xyz="0 0 0.124"/>
            <geometry>
                <box size="0.017 0.009 0.248"/>
            </geometry>
            <material name="legGrey"/>
        </visual>
        <collision>
            <origin rpy="0 0 0" xyz="0 0 0.124"/>
            <geometry>
                <box size="0.017 0.009 0.248"/>
            </geometry>
        </collision>
        <inertial>
            <origin xyz="0.000000 0.000000 0.144667" quat="0.000000 0.000000 0.000000 1.000000"/>
            <mass value="0.060000002"/>
            <inertia ixx="0.00047772331" ixy="0" ixz="0" iyy="0.00047950333" iyz="0" izz="2.7177999e-05"/>
        </inertial>
        <collision>
            <origin xyz="0.000000 0.000000 0.248000" quat="0.000000 0.000000 0.000000 1.000000"/>
            <geometry>
                <sphere radius="0.015"/>
            </geometry>
        </collision>
        <visual>
            <origin xyz="0.000000 0.000000 0.248000" quat="0.000000 0.000000 0.000000 1.000000"/>
            <geometry>
                <sphere radius="0.015"/>
            </geometry>
            <material name="black"/>
        </visual>
    </link>
    <joint name="10" type="continuous">
        <axis xyz="0 1 0"/>
        <parent link="motor_front_leftL_link"/>
        <child link="lower_leg_front_leftL_link"/>
        <origin xyz="0.000000 0.095000 -0.022998" quat="-0.707090 0.000000 0.000000 0.707123"/>
        <limit effort="100" velocity="100"/>
        <joint_properties damping="0.0" friction="0.0"/>
    </joint>
    <!-- Toe -->
    <link name="lower_leg_back_rightR_link">
        <contact>
            <friction_anchor/>
            <stiffness value="3000.0"/>
            <damping value="100.0"/>
            <spinning_friction value=".05"/>
            <lateral_friction value="1"/>
        </contact>
        <visual>
            <origin rpy="0 0 0" xyz="0 0 0.124"/>
            <geometry>
                <box size="0.017 0.009 0.248"/>
            </geometry>
            <material name="legGrey"/>
        </visual>
        <collision>
            <origin rpy="0 0 0" xyz="0 0 0.124"/>
            <geometry>
                <box size="0.017 0.009 0.248"/>
            </geometry>
        </collision>
        <inertial>
            <origin xyz="0.000000 0.000000 0.144667" quat="0.000000 0.000000 0.000000 1.000000"/>
            <mass value="0.060000002"/>
            <inertia ixx="0.00047772331" ixy="0" ixz="0" iyy="0.00047950333" iyz="0" izz="2.7177999e-05"/>
        </inertial>
        <collision>
            <origin xyz="0.000000 0.000000 0.248000" quat="0.000000 0.000000 0.000000 1.000000"/>
            <geometry>
                <sphere radius="0.015"/>
            </geometry>
        </collision>
        <visual>
            <origin xyz="0.000000 0.000000 0.248000" quat="0.000000 0.000000 0.000000 1.000000"/>
            <geometry>
                <sphere radius="0.015"/>
            </geometry>
            <material name="black"/>
        </visual>
    </link>
    <joint name="12" type="continuous">
        <axis xyz="0 1 0"/>
        <parent link="motor_back_rightR_link"/>
        <child link="lower_leg_back_rightR_link"/>
        <origin xyz="0.000000 0.095000 -0.022998" quat="-0.707090 0.000000 0.000000 0.707123"/>
        <limit effort="100" velocity="100"/>
        <joint_properties damping="0.0" friction="0.0"/>
    </joint>
    <!-- Toe -->
    <link name="lower_leg_back_rightL_link">
        <contact>
            <friction_anchor/>
            <stiffness value="3000.0"/>
            <damping value="100.0"/>
            <spinning_friction value=".05"/>
            <lateral_friction value="1"/>
        </contact>
        <visual>
            <origin rpy="0 0 0" xyz="0 0 0.1"/>
            <geometry>
                <box size="0.017 0.009 0.2"/>
            </geometry>
            <material name="legGrey"/>
        </visual>
        <collision>
            <origin rpy="0 0 0" xyz="0 0 0.1"/>
            <geometry>
                <box size="0.017 0.009 0.2"/>
            </geometry>
        </collision>
        <inertial>
            <origin rpy="0 0 0" xyz="0 0 0.1"/>
            <mass value="0.05"/>
            <inertia ixx=".00032459" ixy=".0" ixz=".0" iyy=".00032637" iyz=".0" izz=".000002178"/>
        </inertial>
    </link>
    <joint name="13" type="continuous">
        <axis xyz="0 1 0"/>
        <parent link="motor_back_rightL_link"/>
        <child link="lower_leg_back_rightL_link"/>
        <origin xyz="0.000000 0.095000 -0.022998" quat="-0.707090 0.000000 0.000000 0.707123"/>
        <limit effort="100" velocity="100"/>
        <joint_properties damping="0.0" friction="0.0"/>
    </joint>
    <link name="lower_leg_back_leftR_link">
        <contact>
            <friction_anchor/>
            <stiffness value="3000.0"/>
            <damping value="100.0"/>
            <spinning_friction value=".05"/>
            <lateral_friction value="1"/>
        </contact>
        <visual>
            <origin rpy="0 0 0" xyz="0 0 0.1"/>
            <geometry>
                <box size="0.017 0.009 0.2"/>
            </geometry>
            <material name="legGrey"/>
        </visual>
        <collision>
            <origin rpy="0 0 0" xyz="0 0 0.1"/>
            <geometry>
                <box size="0.017 0.009 0.2"/>
            </geometry>
        </collision>
        <inertial>
            <origin rpy="0 0 0" xyz="0 0 0.1"/>
            <mass value="0.05"/>
            <inertia ixx=".00032459" ixy=".0" ixz=".0" iyy=".00032637" iyz=".0" izz=".000002178"/>
        </inertial>
    </link>
    <joint name="14" type="continuous">
        <axis xyz="0 1 0"/>
        <parent link="motor_back_leftR_link"/>
        <child link="lower_leg_back_leftR_link"/>
        <origin xyz="0.000000 0.095000 -0.022998" quat="-0.707090 0.000000 0.000000 0.707123"/>
        <limit effort="100" velocity="100"/>
        <joint_properties damping="0.0" friction="0.0"/>
    </joint>
    <link name="lower_leg_back_leftL_link">
        <contact>
            <friction_anchor/>
            <stiffness value="3000.0"/>
            <damping value="100.0"/>
            <spinning_friction value=".05"/>
            <lateral_friction value="1"/>
        </contact>
        <visual>
            <origin rpy="0 0 0" xyz="0 0 0.124"/>
            <geometry>
                <box size="0.017 0.009 0.248"/>
            </geometry>
            <material name="legGrey"/>
        </visual>
        <collision>
            <origin rpy="0 0 0" xyz="0 0 0.124"/>
            <geometry>
                <box size="0.017 0.009 0.248"/>
            </geometry>
        </collision>
        <inertial>
            <origin xyz="0.000000 0.000000 0.144667" quat="0.000000 0.000000 0.000000 1.000000"/>
            <mass value="0.060000002"/>
            <inertia ixx="0.00047772331" ixy="0" ixz="0" iyy="0.00047950333" iyz="0" izz="2.7177999e-05"/>
        </inertial>
        <collision>
            <origin xyz="0.000000 0.000000 0.248000" quat="0.000000 0.000000 0.000000 1.000000"/>
            <geometry>
                <sphere radius="0.015"/>
            </geometry>
        </collision>
        <visual>
            <origin xyz="0.000000 0.000000 0.248000" quat="0.000000 0.000000 0.000000 1.000000"/>
            <geometry>
                <sphere radius="0.015"/>
            </geometry>
            <material name="black"/>
        </visual>
    </link>
    <joint name="15" type="continuous">
        <axis xyz="0 1 0"/>
        <parent link="motor_back_leftL_link"/>
        <child link="lower_leg_back_leftL_link"/>
        <origin xyz="0.000000 0.095000 -0.022998" quat="-0.707090 0.000000 0.000000 0.707123"/>
        <limit effort="100" velocity="100"/>
        <joint_properties damping="0.0" friction="0.0"/>
    </joint>
    <!-- Toe -->
</robot>
