xml version="1.0" ?>
<!-- =================================================================================== -->
<!-- |    This document was autogenerated by xacro from yumi.urdf.xacro                | -->
<!-- |    EDITING THIS FILE BY HAND IS NOT RECOMMENDED                                 | -->
<!-- =================================================================================== -->
<robot name="yumi" xmlns:xacro="http://www.ros.org/wiki/xacro">
  <!-- Import Rviz colors -->
  <material name="Black">
    <color rgba="0.0 0.0 0.0 1.0"/>
  </material>
  <material name="Blue">
    <color rgba="0.0 0.0 0.8 1.0"/>
  </material>
  <material name="Green">
    <color rgba="0.0 0.8 0.0 1.0"/>
  </material>
  <material name="Grey">
    <color rgba="0.5 0.5 0.5 1.0"/>
  </material>
  <material name="Light_Grey">
    <color rgba="0.8 0.8 0.8 1.0"/>
  </material>
  <material name="Ivory">
    <color rgba="1.0 1.0 0.94 1.0"/>
  </material>
  <material name="Orange">
    <color rgba="1.0 0.423529411765 0.0392156862745 1.0"/>
  </material>
  <material name="Brown">
    <color rgba="0.870588235294 0.811764705882 0.764705882353 1.0"/>
  </material>
  <material name="Red">
    <color rgba="0.8 0.0 0.0 1.0"/>
  </material>
  <material name="White">
    <color rgba="1.0 1.0 1.0 1.0"/>
  </material>
  <!-- Import utilities -->
  <!-- The following macros are adapted from the LWR 4 definitions of the RCPRG - https://github.com/RCPRG-ros-pkg/lwr_robot -->
  <!--Little helper macros to define the inertia matrix needed for links.-->
  <!--Cuboid-->
  <!--Cylinder: length is along the y-axis! -->
  <!--Import the yumi macro -->
  <!-- Import all Gazebo-customization elements, including Gazebo colors -->
  <!-- Import Transmissions -->
  <!-- Include Utilities -->
  <!-- The following macros are adapted from the LWR 4 definitions of the RCPRG - https://github.com/RCPRG-ros-pkg/lwr_robot -->
  <!--Little helper macros to define the inertia matrix needed for links.-->
  <!--Cuboid-->
  <!--Cylinder: length is along the y-axis! -->
  <!-- some constants -->
  <!-- <xacro:property name="safety_controller_k_pos" value="100" />
  <xacro:property name="safety_controller_k_vel" value="2" /> -->
  <!--Import the yumi servo gripper macro -->
  <!-- Import all Gazebo-customization elements, including Gazebo colors -->
  <!-- Import Transmissions -->
  <!-- Include Utilities -->
  <!-- The following macros are adapted from the LWR 4 definitions of the RCPRG - https://github.com/RCPRG-ros-pkg/lwr_robot -->
  <!--Little helper macros to define the inertia matrix needed for links.-->
  <!--Cuboid-->
  <!--Cylinder: length is along the y-axis! -->
  <!-- some constants -->
  <!-- <xacro:property name="safety_controller_k_pos" value="100" />
  <xacro:property name="safety_controller_k_vel" value="2" /> -->
  <!-- Import Gazebo plugins -->
  <gazebo>
    <plugin filename="libgazebo_ros_control.so" name="gazebo_ros_controller">
      <robotNamespace>/yumi</robotNamespace>
    </plugin>
  </gazebo>
  <!-- Fix to world just for testing -->

  <!-- <link name="world"/> -->
  
  <!--yumi-->
  <!--joint between {parent} and body-->
<!--   <joint name="world_joint" type="fixed">
    <origin rpy="0 0 0" xyz="0 0 0.1"/>
    <parent link="world"/>
    <child link="base_link"/>
  </joint>
 -->  
  
  <link name="gripper_r_base">
    <inertial>
      <origin rpy="0 0 0" xyz="0 0 0"/>
      <mass value="0.2"/>
      <inertia ixx="0.0001" ixy="0" ixz="0" iyy="0.0001" iyz="0" izz="0.0001"/>
    </inertial>
    <visual>
      <origin rpy="0 0 0" xyz="0 0 0"/>
      <geometry>
        <mesh filename="package://yumi_description/meshes/gripper/base.stl"/>
      </geometry>
      <material name="Light_Grey"/>
    </visual>
    <collision>
      <origin rpy="0 0 0" xyz="0 0 0"/>
      <geometry>
        <mesh filename="package://yumi_description/meshes/gripper/coarse/base_sim_out.obj"/>
      </geometry>
      <material name="Light_Grey"/>
    </collision>
  </link>
  <!-- joint between base and right finger -->
  <joint name="gripper_r_joint" type="prismatic">
    <parent link="gripper_r_base"/>
    <child link="gripper_r_finger_r"/>
    <origin rpy="0 0 0" xyz="0 -0.005 0.0837"/>
    <axis xyz="-1 0 0"/>
    <limit effort="300" lower="0" upper="0.025" velocity="0.02"/>
    <!--   <safety_controller soft_lower_limit="${-168 * M_PI / 180}"
           soft_upper_limit="${168 * M_PI / 180}"
           k_position="${safety_controller_k_pos}"
           k_velocity="${safety_controller_k_vel}"/> -->
    <dynamics damping="0.5"/>
  </joint>
  <link name="gripper_r_finger_r">
    <inertial>
      <origin rpy="0 0 0" xyz="0 0 0"/>
      <mass value="0.01"/>
      <inertia ixx="0.000001" ixy="0" ixz="0" iyy="0.000001" iyz="0" izz="0.000001"/>
    </inertial>
    <visual>
      <origin rpy="0 0 0" xyz="0 0 0"/>
      <geometry>
        <mesh filename="package://yumi_description/meshes/gripper/finger.stl"/>
      </geometry>
      <material name="Grey"/>
    </visual>
    <collision>
      <origin rpy="0 0 0" xyz="0 0 0"/>
      <geometry>
        <mesh filename="package://yumi_description/meshes/gripper/coarse/finger_sim_out_fix.obj"/>
      </geometry>
      <material name="Grey"/>
    </collision>
  </link>
  <!-- joint between base and left finger -->
  <joint name="gripper_r_joint_m" type="prismatic">
    <parent link="gripper_r_base"/>
    <child link="gripper_r_finger_l"/>
    <origin rpy="0 0 3.14159265359" xyz="0 0.005 0.0837"/>
    <axis xyz="-1 0 0"/>
    <limit effort="300" lower="0" upper="0.025" velocity="0.02"/>
    <!--   <safety_controller soft_lower_limit="${-168 * M_PI / 180}"
           soft_upper_limit="${168 * M_PI / 180}"
           k_position="${safety_controller_k_pos}"
           k_velocity="${safety_controller_k_vel}"/> -->
    <dynamics damping="0.5"/>
    <mimic joint="gripper_r_joint"/>
  </joint>
  <link name="gripper_r_finger_l">
    <inertial>
      <origin rpy="0 0 0" xyz="0 0 0"/>
      <mass value="0.01"/>
      <inertia ixx="0.000001" ixy="0" ixz="0" iyy="0.000001" iyz="0" izz="0.000001"/>
    </inertial>
    <visual>
      <origin rpy="0 0 0" xyz="0 0 0"/>
      <geometry>
        <mesh filename="package://yumi_description/meshes/gripper/finger.stl"/>
      </geometry>
      <material name="Grey"/>
    </visual>
    <collision>
      <origin rpy="0 0 0" xyz="0 0 0"/>
      <geometry>
        <mesh filename="package://yumi_description/meshes/gripper/coarse/finger_sim_out_fix.obj"/>
      </geometry>
      <material name="Grey"/>
    </collision>
  </link>
</robot>
