<?xml version="1.0"?>
<!--
Software License Agreement (BSD)

\file      i2_wheel.urdf.xacro
\authors   Patrick Hussey
\copyright Copyright (c) 2015, Stanley Innovation, Inc., All rights reserved.

Redistribution and use in source and binary forms, with or without modification, are permitted provided that
the following conditions are met:
 * Redistributions of source code must retain the above copyright notice, this list of conditions and the
   following disclaimer.
 * Redistributions in binary form must reproduce the above copyright notice, this list of conditions and the
   following disclaimer in the documentation and/or other materials provided with the distribution.
 * Neither the name of Stanley Innovation, Inc. nor the names of its contributors may be used to endorse or promote
   products derived from this software without specific prior written permission.

THIS SOFTWARE IS PROVIDED BY THE COPYRIGHT HOLDERS AND CONTRIBUTORS "AS IS" AND ANY EXPRESS OR IMPLIED WAR-
RANTIES, INCLUDING, BUT NOT LIMITED TO, THE IMPLIED WARRANTIES OF MERCHANTABILITY AND FITNESS FOR A PARTICULAR
PURPOSE ARE DISCLAIMED. IN NO EVENT SHALL THE COPYRIGHT HOLDER OR CONTRIBUTORS BE LIABLE FOR ANY DIRECT, IN-
DIRECT, INCIDENTAL, SPECIAL, EXEMPLARY, OR CONSEQUENTIAL DAMAGES (INCLUDING, BUT NOT LIMITED TO, PROCUREMENT
OF SUBSTITUTE GOODS OR SERVICES; LOSS OF USE, DATA, OR PROFITS; OR BUSINESS INTERRUPTION) HOWEVER CAUSED AND
ON ANY THEORY OF LIABILITY, WHETHER IN CONTRACT, STRICT LIABILITY, OR TORT (INCLUDING NEGLIGENCE OR OTHERWISE)
ARISING IN ANY WAY OUT OF THE USE OF THIS SOFTWARE, EVEN IF ADVISED OF THE POSSIBILITY OF SUCH DAMAGE.
-->
<robot xmlns:xacro="http://ros.org/wiki/xacro" name="i2_wheel">

	<xacro:macro name="i2_wheel" params="wheel_prefix parent visual_rotation *joint_pose">
		<link name="${wheel_prefix}_wheel_link">
			<inertial>
				<mass value="4.195729" />
				<origin xyz="0 0 0" />
				<inertia  ixx="0.063680" ixy="0.000000" ixz="0.000000"
                          iyx="0.000000" iyy="0.121410" iyz="0.000000"
                          izx="0.000000" izy="0.000000" izz="0.063680" />
			</inertial>
			<visual>
			    <origin xyz="0 0 0" rpy="0 0 ${visual_rotation}"/>
				<geometry>
					<mesh filename="package://segway_description/meshes/visual/i2_wheel.dae" />
				</geometry>
			</visual>
			<collision>
			    <origin xyz="0 0 0" rpy="${M_PI / 2.0} 0 0"/>
				<geometry>
				    <cylinder length="0.092249" radius="0.2405681"/>
				</geometry>
			</collision>
		</link>

		<gazebo reference="${wheel_prefix}_wheel_link">
			<mu1 value="10.0"/>
			<mu2 value="10.0"/>
			<kp value="10000000.0" />
			<kd value="10.0" />
			<fdir1 value="1 0 0"/>
			<minDepth>0.003</minDepth>
		</gazebo>

		<joint name="${wheel_prefix}_wheel" type="continuous">
			<parent link="${parent}"/>
			<child link="${wheel_prefix}_wheel_link"/>
			<xacro:insert_block name="joint_pose"/>
			<axis xyz="0 1 0" rpy="0 0 0" />
		</joint>

		<transmission name="${wheel_prefix}_wheel_trans" type="SimpleTransmission">
			<type>transmission_interface/SimpleTransmission</type>
			<actuator name="${wheel_prefix}_wheel_motor">
				<mechanicalReduction>1</mechanicalReduction>
			</actuator>
			<joint name="${wheel_prefix}_wheel">
				<hardwareInterface>VelocityJointInterface</hardwareInterface>
			</joint>
		</transmission>

	</xacro:macro>
</robot>
